{
  "size": [
    31,
    48,
    31
  ],
  "anchor": [
    15,
    3,
    15
  ],
  "chest": [
    2,
    4,
    15
  ],
  "palette": [
    {
      "Name": "minecraft:dirt"
    },
    {
      "Name": "minecraft:grass_block"
    },
    {
      "Name": "minecraft:moss_block"
    },
    {
      "Name": "minecraft:coarse_dirt"
    },
    {
      "Name": "minecraft:cobblestone"
    },
    {
      "Name": "minecraft:andesite"
    },
    {
      "Name": "minecraft:mossy_cobblestone"
    },
    {
      "Name": "minecraft:mossy_stone_bricks"
    },
    {
      "Name": "minecraft:stone_bricks"
    },
    {
      "Name": "minecraft:cracked_stone_bricks"
    },
    {
      "Name": "minecraft:chiseled_stone_bricks"
    },
    {
      "Name": "minecraft:air"
    },
    {
      "Name": "minecraft:oak_log",
      "Properties": {
        "axis": "y"
      }
    },
    {
      "Name": "minecraft:dark_oak_log",
      "Properties": {
        "axis": "z"
      }
    },
    {
      "Name": "minecraft:chest",
      "Properties": {
        "facing": "east",
        "type": "single",
        "waterlogged": "false"
      }
    },
    {
      "Name": "minecraft:dark_oak_log",
      "Properties": {
        "axis": "x"
      }
    },
    {
      "Name": "minecraft:mossy_stone_brick_slab",
      "Properties": {
        "type": "bottom",
        "waterlogged": "false"
      }
    }
  ],
  "blocks": [
    {
      "pos": [
        0,
        3,
        13
      ],
      "state": 1
    },
    {
      "pos": [
        0,
        3,
        14
      ],
      "state": 2
    },
    {
      "pos": [
        0,
        3,
        15
      ],
      "state": 1
    },
    {
      "pos": [
        0,
        3,
        16
      ],
      "state": 1
    },
    {
      "pos": [
        0,
        3,
        17
      ],
      "state": 3
    },
    {
      "pos": [
        1,
        3,
        9
      ],
      "state": 1
    },
    {
      "pos": [
        1,
        3,
        10
      ],
      "state": 1
    },
    {
      "pos": [
        1,
        3,
        11
      ],
      "state": 1
    },
    {
      "pos": [
        1,
        3,
        12
      ],
      "state": 1
    },
    {
      "pos": [
        1,
        3,
        13
      ],
      "state": 3
    },
    {
      "pos": [
        1,
        3,
        14
      ],
      "state": 3
    },
    {
      "pos": [
        1,
        3,
        15
      ],
      "state": 1
    },
    {
      "pos": [
        1,
        3,
        16
      ],
      "state": 1
    },
    {
      "pos": [
        1,
        3,
        17
      ],
      "state": 1
    },
    {
      "pos": [
        1,
        3,
        18
      ],
      "state": 1
    },
    {
      "pos": [
        1,
        3,
        19
      ],
      "state": 1
    },
    {
      "pos": [
        1,
        3,
        20
      ],
      "state": 1
    },
    {
      "pos": [
        1,
        3,
        21
      ],
      "state": 1
    },
    {
      "pos": [
        2,
        3,
        8
      ],
      "state": 1
    },
    {
      "pos": [
        2,
        3,
        9
      ],
      "state": 1
    },
    {
      "pos": [
        2,
        3,
        10
      ],
      "state": 1
    },
    {
      "pos": [
        2,
        3,
        11
      ],
      "state": 1
    },
    {
      "pos": [
        2,
        3,
        12
      ],
      "state": 3
    },
    {
      "pos": [
        2,
        3,
        13
      ],
      "state": 1
    },
    {
      "pos": [
        2,
        3,
        14
      ],
      "state": 3
    },
    {
      "pos": [
        2,
        3,
        15
      ],
      "state": 4
    },
    {
      "pos": [
        2,
        3,
        16
      ],
      "state": 1
    },
    {
      "pos": [
        2,
        3,
        17
      ],
      "state": 1
    },
    {
      "pos": [
        2,
        3,
        18
      ],
      "state": 1
    },
    {
      "pos": [
        2,
        3,
        19
      ],
      "state": 1
    },
    {
      "pos": [
        2,
        3,
        20
      ],
      "state": 1
    },
    {
      "pos": [
        2,
        3,
        21
      ],
      "state": 1
    },
    {
      "pos": [
        2,
        3,
        22
      ],
      "state": 1
    },
    {
      "pos": [
        3,
        3,
        6
      ],
      "state": 2
    },
    {
      "pos": [
        3,
        3,
        7
      ],
      "state": 1
    },
    {
      "pos": [
        3,
        3,
        8
      ],
      "state": 1
    },
    {
      "pos": [
        3,
        3,
        9
      ],
      "state": 1
    },
    {
      "pos": [
        3,
        3,
        10
      ],
      "state": 4
    },
    {
      "pos": [
        3,
        3,
        11
      ],
      "state": 4
    },
    {
      "pos": [
        3,
        3,
        12
      ],
      "state": 4
    },
    {
      "pos": [
        3,
        3,
        13
      ],
      "state": 4
    },
    {
      "pos": [
        3,
        3,
        14
      ],
      "state": 5
    },
    {
      "pos": [
        3,
        3,
        15
      ],
      "state": 4
    },
    {
      "pos": [
        3,
        3,
        16
      ],
      "state": 4
    },
    {
      "pos": [
        3,
        3,
        17
      ],
      "state": 4
    },
    {
      "pos": [
        3,
        3,
        18
      ],
      "state": 4
    },
    {
      "pos": [
        3,
        3,
        19
      ],
      "state": 6
    },
    {
      "pos": [
        3,
        3,
        20
      ],
      "state": 6
    },
    {
      "pos": [
        3,
        3,
        21
      ],
      "state": 2
    },
    {
      "pos": [
        3,
        3,
        22
      ],
      "state": 1
    },
    {
      "pos": [
        3,
        3,
        23
      ],
      "state": 1
    },
    {
      "pos": [
        3,
        3,
        24
      ],
      "state": 1
    },
    {
      "pos": [
        4,
        3,
        5
      ],
      "state": 1
    },
    {
      "pos": [
        4,
        3,
        6
      ],
      "state": 1
    },
    {
      "pos": [
        4,
        3,
        7
      ],
      "state": 1
    },
    {
      "pos": [
        4,
        3,
        8
      ],
      "state": 3
    },
    {
      "pos": [
        4,
        3,
        9
      ],
      "state": 6
    },
    {
      "pos": [
        4,
        3,
        10
      ],
      "state": 5
    },
    {
      "pos": [
        4,
        3,
        11
      ],
      "state": 4
    },
    {
      "pos": [
        4,
        3,
        12
      ],
      "state": 5
    },
    {
      "pos": [
        4,
        3,
        13
      ],
      "state": 4
    },
    {
      "pos": [
        4,
        3,
        14
      ],
      "state": 5
    },
    {
      "pos": [
        4,
        3,
        15
      ],
      "state": 5
    },
    {
      "pos": [
        4,
        3,
        16
      ],
      "state": 5
    },
    {
      "pos": [
        4,
        3,
        17
      ],
      "state": 6
    },
    {
      "pos": [
        4,
        3,
        18
      ],
      "state": 4
    },
    {
      "pos": [
        4,
        3,
        19
      ],
      "state": 6
    },
    {
      "pos": [
        4,
        3,
        20
      ],
      "state": 5
    },
    {
      "pos": [
        4,
        3,
        21
      ],
      "state": 5
    },
    {
      "pos": [
        4,
        3,
        22
      ],
      "state": 1
    },
    {
      "pos": [
        4,
        3,
        23
      ],
      "state": 2
    },
    {
      "pos": [
        4,
        3,
        24
      ],
      "state": 3
    },
    {
      "pos": [
        4,
        3,
        25
      ],
      "state": 1
    },
    {
      "pos": [
        5,
        3,
        4
      ],
      "state": 1
    },
    {
      "pos": [
        5,
        3,
        5
      ],
      "state": 7
    },
    {
      "pos": [
        5,
        3,
        6
      ],
      "state": 8
    },
    {
      "pos": [
        5,
        3,
        7
      ],
      "state": 5
    },
    {
      "pos": [
        5,
        3,
        8
      ],
      "state": 4
    },
    {
      "pos": [
        5,
        3,
        9
      ],
      "state": 5
    },
    {
      "pos": [
        5,
        3,
        10
      ],
      "state": 5
    },
    {
      "pos": [
        5,
        3,
        11
      ],
      "state": 9
    },
    {
      "pos": [
        5,
        3,
        12
      ],
      "state": 9
    },
    {
      "pos": [
        5,
        3,
        13
      ],
      "state": 7
    },
    {
      "pos": [
        5,
        3,
        14
      ],
      "state": 8
    },
    {
      "pos": [
        5,
        3,
        15
      ],
      "state": 7
    },
    {
      "pos": [
        5,
        3,
        16
      ],
      "state": 8
    },
    {
      "pos": [
        5,
        3,
        17
      ],
      "state": 7
    },
    {
      "pos": [
        5,
        3,
        18
      ],
      "state": 9
    },
    {
      "pos": [
        5,
        3,
        19
      ],
      "state": 9
    },
    {
      "pos": [
        5,
        3,
        20
      ],
      "state": 5
    },
    {
      "pos": [
        5,
        3,
        21
      ],
      "state": 4
    },
    {
      "pos": [
        5,
        3,
        22
      ],
      "state": 5
    },
    {
      "pos": [
        5,
        3,
        23
      ],
      "state": 5
    },
    {
      "pos": [
        5,
        3,
        24
      ],
      "state": 8
    },
    {
      "pos": [
        5,
        3,
        25
      ],
      "state": 7
    },
    {
      "pos": [
        5,
        3,
        26
      ],
      "state": 1
    },
    {
      "pos": [
        6,
        3,
        3
      ],
      "state": 1
    },
    {
      "pos": [
        6,
        3,
        4
      ],
      "state": 1
    },
    {
      "pos": [
        6,
        3,
        5
      ],
      "state": 7
    },
    {
      "pos": [
        6,
        3,
        6
      ],
      "state": 4
    },
    {
      "pos": [
        6,
        3,
        7
      ],
      "state": 5
    },
    {
      "pos": [
        6,
        3,
        8
      ],
      "state": 5
    },
    {
      "pos": [
        6,
        3,
        9
      ],
      "state": 9
    },
    {
      "pos": [
        6,
        3,
        10
      ],
      "state": 9
    },
    {
      "pos": [
        6,
        3,
        11
      ],
      "state": 7
    },
    {
      "pos": [
        6,
        3,
        12
      ],
      "state": 8
    },
    {
      "pos": [
        6,
        3,
        13
      ],
      "state": 7
    },
    {
      "pos": [
        6,
        3,
        14
      ],
      "state": 8
    },
    {
      "pos": [
        6,
        3,
        15
      ],
      "state": 9
    },
    {
      "pos": [
        6,
        3,
        16
      ],
      "state": 7
    },
    {
      "pos": [
        6,
        3,
        17
      ],
      "state": 9
    },
    {
      "pos": [
        6,
        3,
        18
      ],
      "state": 9
    },
    {
      "pos": [
        6,
        3,
        19
      ],
      "state": 7
    },
    {
      "pos": [
        6,
        3,
        20
      ],
      "state": 7
    },
    {
      "pos": [
        6,
        3,
        21
      ],
      "state": 8
    },
    {
      "pos": [
        6,
        3,
        22
      ],
      "state": 4
    },
    {
      "pos": [
        6,
        3,
        23
      ],
      "state": 4
    },
    {
      "pos": [
        6,
        3,
        24
      ],
      "state": 5
    },
    {
      "pos": [
        6,
        3,
        25
      ],
      "state": 9
    },
    {
      "pos": [
        6,
        3,
        26
      ],
      "state": 1
    },
    {
      "pos": [
        6,
        3,
        27
      ],
      "state": 1
    },
    {
      "pos": [
        7,
        3,
        3
      ],
      "state": 1
    },
    {
      "pos": [
        7,
        3,
        4
      ],
      "state": 1
    },
    {
      "pos": [
        7,
        3,
        5
      ],
      "state": 6
    },
    {
      "pos": [
        7,
        3,
        6
      ],
      "state": 5
    },
    {
      "pos": [
        7,
        3,
        7
      ],
      "state": 5
    },
    {
      "pos": [
        7,
        3,
        8
      ],
      "state": 7
    },
    {
      "pos": [
        7,
        3,
        9
      ],
      "state": 9
    },
    {
      "pos": [
        7,
        3,
        10
      ],
      "state": 9
    },
    {
      "pos": [
        7,
        3,
        11
      ],
      "state": 9
    },
    {
      "pos": [
        7,
        3,
        12
      ],
      "state": 8
    },
    {
      "pos": [
        7,
        3,
        13
      ],
      "state": 8
    },
    {
      "pos": [
        7,
        3,
        14
      ],
      "state": 7
    },
    {
      "pos": [
        7,
        3,
        15
      ],
      "state": 8
    },
    {
      "pos": [
        7,
        3,
        16
      ],
      "state": 9
    },
    {
      "pos": [
        7,
        3,
        17
      ],
      "state": 7
    },
    {
      "pos": [
        7,
        3,
        18
      ],
      "state": 8
    },
    {
      "pos": [
        7,
        3,
        19
      ],
      "state": 8
    },
    {
      "pos": [
        7,
        3,
        20
      ],
      "state": 9
    },
    {
      "pos": [
        7,
        3,
        21
      ],
      "state": 9
    },
    {
      "pos": [
        7,
        3,
        22
      ],
      "state": 8
    },
    {
      "pos": [
        7,
        3,
        23
      ],
      "state": 5
    },
    {
      "pos": [
        7,
        3,
        24
      ],
      "state": 6
    },
    {
      "pos": [
        7,
        3,
        25
      ],
      "state": 5
    },
    {
      "pos": [
        7,
        3,
        26
      ],
      "state": 1
    },
    {
      "pos": [
        7,
        3,
        27
      ],
      "state": 1
    },
    {
      "pos": [
        8,
        3,
        2
      ],
      "state": 1
    },
    {
      "pos": [
        8,
        3,
        3
      ],
      "state": 1
    },
    {
      "pos": [
        8,
        3,
        4
      ],
      "state": 1
    },
    {
      "pos": [
        8,
        3,
        5
      ],
      "state": 6
    },
    {
      "pos": [
        8,
        3,
        6
      ],
      "state": 4
    },
    {
      "pos": [
        8,
        3,
        7
      ],
      "state": 7
    },
    {
      "pos": [
        8,
        3,
        8
      ],
      "state": 7
    },
    {
      "pos": [
        8,
        3,
        9
      ],
      "state": 7
    },
    {
      "pos": [
        8,
        3,
        10
      ],
      "state": 9
    },
    {
      "pos": [
        8,
        3,
        11
      ],
      "state": 7
    },
    {
      "pos": [
        8,
        3,
        12
      ],
      "state": 9
    },
    {
      "pos": [
        8,
        3,
        13
      ],
      "state": 7
    },
    {
      "pos": [
        8,
        3,
        14
      ],
      "state": 9
    },
    {
      "pos": [
        8,
        3,
        15
      ],
      "state": 8
    },
    {
      "pos": [
        8,
        3,
        16
      ],
      "state": 8
    },
    {
      "pos": [
        8,
        3,
        17
      ],
      "state": 7
    },
    {
      "pos": [
        8,
        3,
        18
      ],
      "state": 7
    },
    {
      "pos": [
        8,
        3,
        19
      ],
      "state": 7
    },
    {
      "pos": [
        8,
        3,
        20
      ],
      "state": 9
    },
    {
      "pos": [
        8,
        3,
        21
      ],
      "state": 7
    },
    {
      "pos": [
        8,
        3,
        22
      ],
      "state": 7
    },
    {
      "pos": [
        8,
        3,
        23
      ],
      "state": 8
    },
    {
      "pos": [
        8,
        3,
        24
      ],
      "state": 5
    },
    {
      "pos": [
        8,
        3,
        25
      ],
      "state": 5
    },
    {
      "pos": [
        8,
        3,
        26
      ],
      "state": 1
    },
    {
      "pos": [
        8,
        3,
        27
      ],
      "state": 2
    },
    {
      "pos": [
        8,
        3,
        28
      ],
      "state": 1
    },
    {
      "pos": [
        9,
        3,
        1
      ],
      "state": 3
    },
    {
      "pos": [
        9,
        3,
        2
      ],
      "state": 2
    },
    {
      "pos": [
        9,
        3,
        3
      ],
      "state": 3
    },
    {
      "pos": [
        9,
        3,
        4
      ],
      "state": 4
    },
    {
      "pos": [
        9,
        3,
        5
      ],
      "state": 6
    },
    {
      "pos": [
        9,
        3,
        6
      ],
      "state": 7
    },
    {
      "pos": [
        9,
        3,
        7
      ],
      "state": 7
    },
    {
      "pos": [
        9,
        3,
        8
      ],
      "state": 8
    },
    {
      "pos": [
        9,
        3,
        9
      ],
      "state": 9
    },
    {
      "pos": [
        9,
        3,
        10
      ],
      "state": 8
    },
    {
      "pos": [
        9,
        3,
        11
      ],
      "state": 8
    },
    {
      "pos": [
        9,
        3,
        12
      ],
      "state": 7
    },
    {
      "pos": [
        9,
        3,
        13
      ],
      "state": 9
    },
    {
      "pos": [
        9,
        3,
        14
      ],
      "state": 7
    },
    {
      "pos": [
        9,
        3,
        15
      ],
      "state": 7
    },
    {
      "pos": [
        9,
        3,
        16
      ],
      "state": 8
    },
    {
      "pos": [
        9,
        3,
        17
      ],
      "state": 7
    },
    {
      "pos": [
        9,
        3,
        18
      ],
      "state": 8
    },
    {
      "pos": [
        9,
        3,
        19
      ],
      "state": 8
    },
    {
      "pos": [
        9,
        3,
        20
      ],
      "state": 8
    },
    {
      "pos": [
        9,
        3,
        21
      ],
      "state": 8
    },
    {
      "pos": [
        9,
        3,
        22
      ],
      "state": 7
    },
    {
      "pos": [
        9,
        3,
        23
      ],
      "state": 7
    },
    {
      "pos": [
        9,
        3,
        24
      ],
      "state": 7
    },
    {
      "pos": [
        9,
        3,
        25
      ],
      "state": 5
    },
    {
      "pos": [
        9,
        3,
        26
      ],
      "state": 5
    },
    {
      "pos": [
        9,
        3,
        27
      ],
      "state": 2
    },
    {
      "pos": [
        9,
        3,
        28
      ],
      "state": 1
    },
    {
      "pos": [
        9,
        3,
        29
      ],
      "state": 1
    },
    {
      "pos": [
        10,
        3,
        1
      ],
      "state": 1
    },
    {
      "pos": [
        10,
        3,
        2
      ],
      "state": 3
    },
    {
      "pos": [
        10,
        3,
        3
      ],
      "state": 4
    },
    {
      "pos": [
        10,
        3,
        4
      ],
      "state": 4
    },
    {
      "pos": [
        10,
        3,
        5
      ],
      "state": 4
    },
    {
      "pos": [
        10,
        3,
        6
      ],
      "state": 7
    },
    {
      "pos": [
        10,
        3,
        7
      ],
      "state": 9
    },
    {
      "pos": [
        10,
        3,
        8
      ],
      "state": 9
    },
    {
      "pos": [
        10,
        3,
        9
      ],
      "state": 9
    },
    {
      "pos": [
        10,
        3,
        10
      ],
      "state": 7
    },
    {
      "pos": [
        10,
        3,
        11
      ],
      "state": 8
    },
    {
      "pos": [
        10,
        3,
        12
      ],
      "state": 8
    },
    {
      "pos": [
        10,
        3,
        13
      ],
      "state": 9
    },
    {
      "pos": [
        10,
        3,
        14
      ],
      "state": 7
    },
    {
      "pos": [
        10,
        3,
        15
      ],
      "state": 9
    },
    {
      "pos": [
        10,
        3,
        16
      ],
      "state": 8
    },
    {
      "pos": [
        10,
        3,
        17
      ],
      "state": 8
    },
    {
      "pos": [
        10,
        3,
        18
      ],
      "state": 7
    },
    {
      "pos": [
        10,
        3,
        19
      ],
      "state": 8
    },
    {
      "pos": [
        10,
        3,
        20
      ],
      "state": 8
    },
    {
      "pos": [
        10,
        3,
        21
      ],
      "state": 7
    },
    {
      "pos": [
        10,
        3,
        22
      ],
      "state": 9
    },
    {
      "pos": [
        10,
        3,
        23
      ],
      "state": 9
    },
    {
      "pos": [
        10,
        3,
        24
      ],
      "state": 8
    },
    {
      "pos": [
        10,
        3,
        25
      ],
      "state": 6
    },
    {
      "pos": [
        10,
        3,
        26
      ],
      "state": 5
    },
    {
      "pos": [
        10,
        3,
        27
      ],
      "state": 5
    },
    {
      "pos": [
        10,
        3,
        28
      ],
      "state": 1
    },
    {
      "pos": [
        10,
        3,
        29
      ],
      "state": 1
    },
    {
      "pos": [
        11,
        3,
        1
      ],
      "state": 1
    },
    {
      "pos": [
        11,
        3,
        2
      ],
      "state": 1
    },
    {
      "pos": [
        11,
        3,
        3
      ],
      "state": 6
    },
    {
      "pos": [
        11,
        3,
        4
      ],
      "state": 4
    },
    {
      "pos": [
        11,
        3,
        5
      ],
      "state": 9
    },
    {
      "pos": [
        11,
        3,
        6
      ],
      "state": 7
    },
    {
      "pos": [
        11,
        3,
        7
      ],
      "state": 7
    },
    {
      "pos": [
        11,
        3,
        8
      ],
      "state": 7
    },
    {
      "pos": [
        11,
        3,
        9
      ],
      "state": 9
    },
    {
      "pos": [
        11,
        3,
        10
      ],
      "state": 7
    },
    {
      "pos": [
        11,
        3,
        11
      ],
      "state": 7
    },
    {
      "pos": [
        11,
        3,
        12
      ],
      "state": 7
    },
    {
      "pos": [
        11,
        3,
        13
      ],
      "state": 9
    },
    {
      "pos": [
        11,
        3,
        14
      ],
      "state": 8
    },
    {
      "pos": [
        11,
        3,
        15
      ],
      "state": 9
    },
    {
      "pos": [
        11,
        3,
        16
      ],
      "state": 8
    },
    {
      "pos": [
        11,
        3,
        17
      ],
      "state": 8
    },
    {
      "pos": [
        11,
        3,
        18
      ],
      "state": 9
    },
    {
      "pos": [
        11,
        3,
        19
      ],
      "state": 8
    },
    {
      "pos": [
        11,
        3,
        20
      ],
      "state": 7
    },
    {
      "pos": [
        11,
        3,
        21
      ],
      "state": 9
    },
    {
      "pos": [
        11,
        3,
        22
      ],
      "state": 8
    },
    {
      "pos": [
        11,
        3,
        23
      ],
      "state": 7
    },
    {
      "pos": [
        11,
        3,
        24
      ],
      "state": 7
    },
    {
      "pos": [
        11,
        3,
        25
      ],
      "state": 7
    },
    {
      "pos": [
        11,
        3,
        26
      ],
      "state": 6
    },
    {
      "pos": [
        11,
        3,
        27
      ],
      "state": 5
    },
    {
      "pos": [
        11,
        3,
        28
      ],
      "state": 1
    },
    {
      "pos": [
        11,
        3,
        29
      ],
      "state": 1
    },
    {
      "pos": [
        12,
        3,
        1
      ],
      "state": 2
    },
    {
      "pos": [
        12,
        3,
        2
      ],
      "state": 1
    },
    {
      "pos": [
        12,
        3,
        3
      ],
      "state": 4
    },
    {
      "pos": [
        12,
        3,
        4
      ],
      "state": 6
    },
    {
      "pos": [
        12,
        3,
        5
      ],
      "state": 9
    },
    {
      "pos": [
        12,
        3,
        6
      ],
      "state": 8
    },
    {
      "pos": [
        12,
        3,
        7
      ],
      "state": 8
    },
    {
      "pos": [
        12,
        3,
        8
      ],
      "state": 7
    },
    {
      "pos": [
        12,
        3,
        9
      ],
      "state": 7
    },
    {
      "pos": [
        12,
        3,
        10
      ],
      "state": 7
    },
    {
      "pos": [
        12,
        3,
        11
      ],
      "state": 7
    },
    {
      "pos": [
        12,
        3,
        12
      ],
      "state": 8
    },
    {
      "pos": [
        12,
        3,
        13
      ],
      "state": 9
    },
    {
      "pos": [
        12,
        3,
        14
      ],
      "state": 9
    },
    {
      "pos": [
        12,
        3,
        15
      ],
      "state": 7
    },
    {
      "pos": [
        12,
        3,
        16
      ],
      "state": 9
    },
    {
      "pos": [
        12,
        3,
        17
      ],
      "state": 9
    },
    {
      "pos": [
        12,
        3,
        18
      ],
      "state": 8
    },
    {
      "pos": [
        12,
        3,
        19
      ],
      "state": 9
    },
    {
      "pos": [
        12,
        3,
        20
      ],
      "state": 7
    },
    {
      "pos": [
        12,
        3,
        21
      ],
      "state": 7
    },
    {
      "pos": [
        12,
        3,
        22
      ],
      "state": 9
    },
    {
      "pos": [
        12,
        3,
        23
      ],
      "state": 7
    },
    {
      "pos": [
        12,
        3,
        24
      ],
      "state": 8
    },
    {
      "pos": [
        12,
        3,
        25
      ],
      "state": 9
    },
    {
      "pos": [
        12,
        3,
        26
      ],
      "state": 5
    },
    {
      "pos": [
        12,
        3,
        27
      ],
      "state": 5
    },
    {
      "pos": [
        12,
        3,
        28
      ],
      "state": 1
    },
    {
      "pos": [
        12,
        3,
        29
      ],
      "state": 1
    },
    {
      "pos": [
        13,
        3,
        0
      ],
      "state": 1
    },
    {
      "pos": [
        13,
        3,
        1
      ],
      "state": 1
    },
    {
      "pos": [
        13,
        3,
        2
      ],
      "state": 1
    },
    {
      "pos": [
        13,
        3,
        3
      ],
      "state": 4
    },
    {
      "pos": [
        13,
        3,
        4
      ],
      "state": 6
    },
    {
      "pos": [
        13,
        3,
        5
      ],
      "state": 7
    },
    {
      "pos": [
        13,
        3,
        6
      ],
      "state": 8
    },
    {
      "pos": [
        13,
        3,
        7
      ],
      "state": 9
    },
    {
      "pos": [
        13,
        3,
        8
      ],
      "state": 9
    },
    {
      "pos": [
        13,
        3,
        9
      ],
      "state": 7
    },
    {
      "pos": [
        13,
        3,
        10
      ],
      "state": 7
    },
    {
      "pos": [
        13,
        3,
        11
      ],
      "state": 8
    },
    {
      "pos": [
        13,
        3,
        12
      ],
      "state": 8
    },
    {
      "pos": [
        13,
        3,
        13
      ],
      "state": 9
    },
    {
      "pos": [
        13,
        3,
        14
      ],
      "state": 9
    },
    {
      "pos": [
        13,
        3,
        15
      ],
      "state": 10
    },
    {
      "pos": [
        13,
        3,
        16
      ],
      "state": 7
    },
    {
      "pos": [
        13,
        3,
        17
      ],
      "state": 9
    },
    {
      "pos": [
        13,
        3,
        18
      ],
      "state": 7
    },
    {
      "pos": [
        13,
        3,
        19
      ],
      "state": 9
    },
    {
      "pos": [
        13,
        3,
        20
      ],
      "state": 9
    },
    {
      "pos": [
        13,
        3,
        21
      ],
      "state": 8
    },
    {
      "pos": [
        13,
        3,
        22
      ],
      "state": 9
    },
    {
      "pos": [
        13,
        3,
        23
      ],
      "state": 7
    },
    {
      "pos": [
        13,
        3,
        24
      ],
      "state": 9
    },
    {
      "pos": [
        13,
        3,
        25
      ],
      "state": 9
    },
    {
      "pos": [
        13,
        3,
        26
      ],
      "state": 4
    },
    {
      "pos": [
        13,
        3,
        27
      ],
      "state": 6
    },
    {
      "pos": [
        13,
        3,
        28
      ],
      "state": 1
    },
    {
      "pos": [
        13,
        3,
        29
      ],
      "state": 1
    },
    {
      "pos": [
        13,
        3,
        30
      ],
      "state": 1
    },
    {
      "pos": [
        14,
        3,
        0
      ],
      "state": 1
    },
    {
      "pos": [
        14,
        3,
        1
      ],
      "state": 1
    },
    {
      "pos": [
        14,
        3,
        2
      ],
      "state": 1
    },
    {
      "pos": [
        14,
        3,
        3
      ],
      "state": 5
    },
    {
      "pos": [
        14,
        3,
        4
      ],
      "state": 6
    },
    {
      "pos": [
        14,
        3,
        5
      ],
      "state": 8
    },
    {
      "pos": [
        14,
        3,
        6
      ],
      "state": 7
    },
    {
      "pos": [
        14,
        3,
        7
      ],
      "state": 8
    },
    {
      "pos": [
        14,
        3,
        8
      ],
      "state": 7
    },
    {
      "pos": [
        14,
        3,
        9
      ],
      "state": 7
    },
    {
      "pos": [
        14,
        3,
        10
      ],
      "state": 7
    },
    {
      "pos": [
        14,
        3,
        11
      ],
      "state": 7
    },
    {
      "pos": [
        14,
        3,
        12
      ],
      "state": 7
    },
    {
      "pos": [
        14,
        3,
        13
      ],
      "state": 9
    },
    {
      "pos": [
        14,
        3,
        14
      ],
      "state": 8
    },
    {
      "pos": [
        14,
        3,
        15
      ],
      "state": 8
    },
    {
      "pos": [
        14,
        3,
        16
      ],
      "state": 7
    },
    {
      "pos": [
        14,
        3,
        17
      ],
      "state": 9
    },
    {
      "pos": [
        14,
        3,
        18
      ],
      "state": 9
    },
    {
      "pos": [
        14,
        3,
        19
      ],
      "state": 7
    },
    {
      "pos": [
        14,
        3,
        20
      ],
      "state": 9
    },
    {
      "pos": [
        14,
        3,
        21
      ],
      "state": 8
    },
    {
      "pos": [
        14,
        3,
        22
      ],
      "state": 8
    },
    {
      "pos": [
        14,
        3,
        23
      ],
      "state": 9
    },
    {
      "pos": [
        14,
        3,
        24
      ],
      "state": 7
    },
    {
      "pos": [
        14,
        3,
        25
      ],
      "state": 9
    },
    {
      "pos": [
        14,
        3,
        26
      ],
      "state": 5
    },
    {
      "pos": [
        14,
        3,
        27
      ],
      "state": 4
    },
    {
      "pos": [
        14,
        3,
        28
      ],
      "state": 2
    },
    {
      "pos": [
        14,
        3,
        29
      ],
      "state": 1
    },
    {
      "pos": [
        14,
        3,
        30
      ],
      "state": 1
    },
    {
      "pos": [
        15,
        3,
        0
      ],
      "state": 1
    },
    {
      "pos": [
        15,
        3,
        1
      ],
      "state": 1
    },
    {
      "pos": [
        15,
        3,
        2
      ],
      "state": 6
    },
    {
      "pos": [
        15,
        3,
        3
      ],
      "state": 6
    },
    {
      "pos": [
        15,
        3,
        4
      ],
      "state": 4
    },
    {
      "pos": [
        15,
        3,
        5
      ],
      "state": 7
    },
    {
      "pos": [
        15,
        3,
        6
      ],
      "state": 8
    },
    {
      "pos": [
        15,
        3,
        7
      ],
      "state": 7
    },
    {
      "pos": [
        15,
        3,
        8
      ],
      "state": 7
    },
    {
      "pos": [
        15,
        3,
        9
      ],
      "state": 8
    },
    {
      "pos": [
        15,
        3,
        10
      ],
      "state": 9
    },
    {
      "pos": [
        15,
        3,
        11
      ],
      "state": 7
    },
    {
      "pos": [
        15,
        3,
        12
      ],
      "state": 7
    },
    {
      "pos": [
        15,
        3,
        13
      ],
      "state": 10
    },
    {
      "pos": [
        15,
        3,
        14
      ],
      "state": 9
    },
    {
      "pos": [
        15,
        3,
        15
      ],
      "state": 2
    },
    {
      "pos": [
        15,
        3,
        16
      ],
      "state": 9
    },
    {
      "pos": [
        15,
        3,
        17
      ],
      "state": 10
    },
    {
      "pos": [
        15,
        3,
        18
      ],
      "state": 8
    },
    {
      "pos": [
        15,
        3,
        19
      ],
      "state": 8
    },
    {
      "pos": [
        15,
        3,
        20
      ],
      "state": 9
    },
    {
      "pos": [
        15,
        3,
        21
      ],
      "state": 9
    },
    {
      "pos": [
        15,
        3,
        22
      ],
      "state": 9
    },
    {
      "pos": [
        15,
        3,
        23
      ],
      "state": 9
    },
    {
      "pos": [
        15,
        3,
        24
      ],
      "state": 9
    },
    {
      "pos": [
        15,
        3,
        25
      ],
      "state": 7
    },
    {
      "pos": [
        15,
        3,
        26
      ],
      "state": 5
    },
    {
      "pos": [
        15,
        3,
        27
      ],
      "state": 5
    },
    {
      "pos": [
        15,
        3,
        28
      ],
      "state": 4
    },
    {
      "pos": [
        15,
        3,
        29
      ],
      "state": 3
    },
    {
      "pos": [
        15,
        3,
        30
      ],
      "state": 1
    },
    {
      "pos": [
        16,
        3,
        0
      ],
      "state": 1
    },
    {
      "pos": [
        16,
        3,
        1
      ],
      "state": 2
    },
    {
      "pos": [
        16,
        3,
        2
      ],
      "state": 1
    },
    {
      "pos": [
        16,
        3,
        3
      ],
      "state": 6
    },
    {
      "pos": [
        16,
        3,
        4
      ],
      "state": 4
    },
    {
      "pos": [
        16,
        3,
        5
      ],
      "state": 7
    },
    {
      "pos": [
        16,
        3,
        6
      ],
      "state": 9
    },
    {
      "pos": [
        16,
        3,
        7
      ],
      "state": 7
    },
    {
      "pos": [
        16,
        3,
        8
      ],
      "state": 7
    },
    {
      "pos": [
        16,
        3,
        9
      ],
      "state": 8
    },
    {
      "pos": [
        16,
        3,
        10
      ],
      "state": 7
    },
    {
      "pos": [
        16,
        3,
        11
      ],
      "state": 9
    },
    {
      "pos": [
        16,
        3,
        12
      ],
      "state": 7
    },
    {
      "pos": [
        16,
        3,
        13
      ],
      "state": 9
    },
    {
      "pos": [
        16,
        3,
        14
      ],
      "state": 9
    },
    {
      "pos": [
        16,
        3,
        15
      ],
      "state": 9
    },
    {
      "pos": [
        16,
        3,
        16
      ],
      "state": 7
    },
    {
      "pos": [
        16,
        3,
        17
      ],
      "state": 8
    },
    {
      "pos": [
        16,
        3,
        18
      ],
      "state": 9
    },
    {
      "pos": [
        16,
        3,
        19
      ],
      "state": 7
    },
    {
      "pos": [
        16,
        3,
        20
      ],
      "state": 9
    },
    {
      "pos": [
        16,
        3,
        21
      ],
      "state": 7
    },
    {
      "pos": [
        16,
        3,
        22
      ],
      "state": 8
    },
    {
      "pos": [
        16,
        3,
        23
      ],
      "state": 8
    },
    {
      "pos": [
        16,
        3,
        24
      ],
      "state": 9
    },
    {
      "pos": [
        16,
        3,
        25
      ],
      "state": 8
    },
    {
      "pos": [
        16,
        3,
        26
      ],
      "state": 4
    },
    {
      "pos": [
        16,
        3,
        27
      ],
      "state": 5
    },
    {
      "pos": [
        16,
        3,
        28
      ],
      "state": 2
    },
    {
      "pos": [
        16,
        3,
        29
      ],
      "state": 1
    },
    {
      "pos": [
        16,
        3,
        30
      ],
      "state": 1
    },
    {
      "pos": [
        17,
        3,
        0
      ],
      "state": 1
    },
    {
      "pos": [
        17,
        3,
        1
      ],
      "state": 2
    },
    {
      "pos": [
        17,
        3,
        2
      ],
      "state": 1
    },
    {
      "pos": [
        17,
        3,
        3
      ],
      "state": 6
    },
    {
      "pos": [
        17,
        3,
        4
      ],
      "state": 4
    },
    {
      "pos": [
        17,
        3,
        5
      ],
      "state": 7
    },
    {
      "pos": [
        17,
        3,
        6
      ],
      "state": 7
    },
    {
      "pos": [
        17,
        3,
        7
      ],
      "state": 7
    },
    {
      "pos": [
        17,
        3,
        8
      ],
      "state": 7
    },
    {
      "pos": [
        17,
        3,
        9
      ],
      "state": 7
    },
    {
      "pos": [
        17,
        3,
        10
      ],
      "state": 7
    },
    {
      "pos": [
        17,
        3,
        11
      ],
      "state": 9
    },
    {
      "pos": [
        17,
        3,
        12
      ],
      "state": 7
    },
    {
      "pos": [
        17,
        3,
        13
      ],
      "state": 9
    },
    {
      "pos": [
        17,
        3,
        14
      ],
      "state": 8
    },
    {
      "pos": [
        17,
        3,
        15
      ],
      "state": 10
    },
    {
      "pos": [
        17,
        3,
        16
      ],
      "state": 7
    },
    {
      "pos": [
        17,
        3,
        17
      ],
      "state": 8
    },
    {
      "pos": [
        17,
        3,
        18
      ],
      "state": 8
    },
    {
      "pos": [
        17,
        3,
        19
      ],
      "state": 8
    },
    {
      "pos": [
        17,
        3,
        20
      ],
      "state": 7
    },
    {
      "pos": [
        17,
        3,
        21
      ],
      "state": 9
    },
    {
      "pos": [
        17,
        3,
        22
      ],
      "state": 7
    },
    {
      "pos": [
        17,
        3,
        23
      ],
      "state": 7
    },
    {
      "pos": [
        17,
        3,
        24
      ],
      "state": 9
    },
    {
      "pos": [
        17,
        3,
        25
      ],
      "state": 8
    },
    {
      "pos": [
        17,
        3,
        26
      ],
      "state": 5
    },
    {
      "pos": [
        17,
        3,
        27
      ],
      "state": 4
    },
    {
      "pos": [
        17,
        3,
        28
      ],
      "state": 1
    },
    {
      "pos": [
        17,
        3,
        29
      ],
      "state": 3
    },
    {
      "pos": [
        17,
        3,
        30
      ],
      "state": 1
    },
    {
      "pos": [
        18,
        3,
        1
      ],
      "state": 2
    },
    {
      "pos": [
        18,
        3,
        2
      ],
      "state": 1
    },
    {
      "pos": [
        18,
        3,
        3
      ],
      "state": 5
    },
    {
      "pos": [
        18,
        3,
        4
      ],
      "state": 6
    },
    {
      "pos": [
        18,
        3,
        5
      ],
      "state": 7
    },
    {
      "pos": [
        18,
        3,
        6
      ],
      "state": 7
    },
    {
      "pos": [
        18,
        3,
        7
      ],
      "state": 9
    },
    {
      "pos": [
        18,
        3,
        8
      ],
      "state": 7
    },
    {
      "pos": [
        18,
        3,
        9
      ],
      "state": 8
    },
    {
      "pos": [
        18,
        3,
        10
      ],
      "state": 7
    },
    {
      "pos": [
        18,
        3,
        11
      ],
      "state": 9
    },
    {
      "pos": [
        18,
        3,
        12
      ],
      "state": 8
    },
    {
      "pos": [
        18,
        3,
        13
      ],
      "state": 8
    },
    {
      "pos": [
        18,
        3,
        14
      ],
      "state": 9
    },
    {
      "pos": [
        18,
        3,
        15
      ],
      "state": 8
    },
    {
      "pos": [
        18,
        3,
        16
      ],
      "state": 8
    },
    {
      "pos": [
        18,
        3,
        17
      ],
      "state": 7
    },
    {
      "pos": [
        18,
        3,
        18
      ],
      "state": 9
    },
    {
      "pos": [
        18,
        3,
        19
      ],
      "state": 9
    },
    {
      "pos": [
        18,
        3,
        20
      ],
      "state": 7
    },
    {
      "pos": [
        18,
        3,
        21
      ],
      "state": 9
    },
    {
      "pos": [
        18,
        3,
        22
      ],
      "state": 8
    },
    {
      "pos": [
        18,
        3,
        23
      ],
      "state": 7
    },
    {
      "pos": [
        18,
        3,
        24
      ],
      "state": 8
    },
    {
      "pos": [
        18,
        3,
        25
      ],
      "state": 7
    },
    {
      "pos": [
        18,
        3,
        26
      ],
      "state": 5
    },
    {
      "pos": [
        18,
        3,
        27
      ],
      "state": 6
    },
    {
      "pos": [
        18,
        3,
        28
      ],
      "state": 1
    },
    {
      "pos": [
        18,
        3,
        29
      ],
      "state": 2
    },
    {
      "pos": [
        19,
        3,
        1
      ],
      "state": 1
    },
    {
      "pos": [
        19,
        3,
        2
      ],
      "state": 2
    },
    {
      "pos": [
        19,
        3,
        3
      ],
      "state": 5
    },
    {
      "pos": [
        19,
        3,
        4
      ],
      "state": 4
    },
    {
      "pos": [
        19,
        3,
        5
      ],
      "state": 7
    },
    {
      "pos": [
        19,
        3,
        6
      ],
      "state": 9
    },
    {
      "pos": [
        19,
        3,
        7
      ],
      "state": 8
    },
    {
      "pos": [
        19,
        3,
        8
      ],
      "state": 9
    },
    {
      "pos": [
        19,
        3,
        9
      ],
      "state": 8
    },
    {
      "pos": [
        19,
        3,
        10
      ],
      "state": 8
    },
    {
      "pos": [
        19,
        3,
        11
      ],
      "state": 7
    },
    {
      "pos": [
        19,
        3,
        12
      ],
      "state": 9
    },
    {
      "pos": [
        19,
        3,
        13
      ],
      "state": 8
    },
    {
      "pos": [
        19,
        3,
        14
      ],
      "state": 7
    },
    {
      "pos": [
        19,
        3,
        15
      ],
      "state": 8
    },
    {
      "pos": [
        19,
        3,
        16
      ],
      "state": 7
    },
    {
      "pos": [
        19,
        3,
        17
      ],
      "state": 9
    },
    {
      "pos": [
        19,
        3,
        18
      ],
      "state": 9
    },
    {
      "pos": [
        19,
        3,
        19
      ],
      "state": 7
    },
    {
      "pos": [
        19,
        3,
        20
      ],
      "state": 7
    },
    {
      "pos": [
        19,
        3,
        21
      ],
      "state": 7
    },
    {
      "pos": [
        19,
        3,
        22
      ],
      "state": 9
    },
    {
      "pos": [
        19,
        3,
        23
      ],
      "state": 7
    },
    {
      "pos": [
        19,
        3,
        24
      ],
      "state": 7
    },
    {
      "pos": [
        19,
        3,
        25
      ],
      "state": 7
    },
    {
      "pos": [
        19,
        3,
        26
      ],
      "state": 4
    },
    {
      "pos": [
        19,
        3,
        27
      ],
      "state": 6
    },
    {
      "pos": [
        19,
        3,
        28
      ],
      "state": 1
    },
    {
      "pos": [
        19,
        3,
        29
      ],
      "state": 1
    },
    {
      "pos": [
        20,
        3,
        1
      ],
      "state": 1
    },
    {
      "pos": [
        20,
        3,
        2
      ],
      "state": 1
    },
    {
      "pos": [
        20,
        3,
        3
      ],
      "state": 5
    },
    {
      "pos": [
        20,
        3,
        4
      ],
      "state": 4
    },
    {
      "pos": [
        20,
        3,
        5
      ],
      "state": 6
    },
    {
      "pos": [
        20,
        3,
        6
      ],
      "state": 8
    },
    {
      "pos": [
        20,
        3,
        7
      ],
      "state": 7
    },
    {
      "pos": [
        20,
        3,
        8
      ],
      "state": 9
    },
    {
      "pos": [
        20,
        3,
        9
      ],
      "state": 9
    },
    {
      "pos": [
        20,
        3,
        10
      ],
      "state": 8
    },
    {
      "pos": [
        20,
        3,
        11
      ],
      "state": 9
    },
    {
      "pos": [
        20,
        3,
        12
      ],
      "state": 9
    },
    {
      "pos": [
        20,
        3,
        13
      ],
      "state": 9
    },
    {
      "pos": [
        20,
        3,
        14
      ],
      "state": 8
    },
    {
      "pos": [
        20,
        3,
        15
      ],
      "state": 8
    },
    {
      "pos": [
        20,
        3,
        16
      ],
      "state": 7
    },
    {
      "pos": [
        20,
        3,
        17
      ],
      "state": 8
    },
    {
      "pos": [
        20,
        3,
        18
      ],
      "state": 9
    },
    {
      "pos": [
        20,
        3,
        19
      ],
      "state": 7
    },
    {
      "pos": [
        20,
        3,
        20
      ],
      "state": 9
    },
    {
      "pos": [
        20,
        3,
        21
      ],
      "state": 9
    },
    {
      "pos": [
        20,
        3,
        22
      ],
      "state": 8
    },
    {
      "pos": [
        20,
        3,
        23
      ],
      "state": 7
    },
    {
      "pos": [
        20,
        3,
        24
      ],
      "state": 7
    },
    {
      "pos": [
        20,
        3,
        25
      ],
      "state": 4
    },
    {
      "pos": [
        20,
        3,
        26
      ],
      "state": 4
    },
    {
      "pos": [
        20,
        3,
        27
      ],
      "state": 5
    },
    {
      "pos": [
        20,
        3,
        28
      ],
      "state": 1
    },
    {
      "pos": [
        20,
        3,
        29
      ],
      "state": 1
    },
    {
      "pos": [
        21,
        3,
        1
      ],
      "state": 1
    },
    {
      "pos": [
        21,
        3,
        2
      ],
      "state": 2
    },
    {
      "pos": [
        21,
        3,
        3
      ],
      "state": 1
    },
    {
      "pos": [
        21,
        3,
        4
      ],
      "state": 6
    },
    {
      "pos": [
        21,
        3,
        5
      ],
      "state": 6
    },
    {
      "pos": [
        21,
        3,
        6
      ],
      "state": 9
    },
    {
      "pos": [
        21,
        3,
        7
      ],
      "state": 7
    },
    {
      "pos": [
        21,
        3,
        8
      ],
      "state": 7
    },
    {
      "pos": [
        21,
        3,
        9
      ],
      "state": 9
    },
    {
      "pos": [
        21,
        3,
        10
      ],
      "state": 8
    },
    {
      "pos": [
        21,
        3,
        11
      ],
      "state": 9
    },
    {
      "pos": [
        21,
        3,
        12
      ],
      "state": 9
    },
    {
      "pos": [
        21,
        3,
        13
      ],
      "state": 8
    },
    {
      "pos": [
        21,
        3,
        14
      ],
      "state": 9
    },
    {
      "pos": [
        21,
        3,
        15
      ],
      "state": 7
    },
    {
      "pos": [
        21,
        3,
        16
      ],
      "state": 7
    },
    {
      "pos": [
        21,
        3,
        17
      ],
      "state": 9
    },
    {
      "pos": [
        21,
        3,
        18
      ],
      "state": 9
    },
    {
      "pos": [
        21,
        3,
        19
      ],
      "state": 8
    },
    {
      "pos": [
        21,
        3,
        20
      ],
      "state": 9
    },
    {
      "pos": [
        21,
        3,
        21
      ],
      "state": 9
    },
    {
      "pos": [
        21,
        3,
        22
      ],
      "state": 7
    },
    {
      "pos": [
        21,
        3,
        23
      ],
      "state": 8
    },
    {
      "pos": [
        21,
        3,
        24
      ],
      "state": 7
    },
    {
      "pos": [
        21,
        3,
        25
      ],
      "state": 5
    },
    {
      "pos": [
        21,
        3,
        26
      ],
      "state": 4
    },
    {
      "pos": [
        21,
        3,
        27
      ],
      "state": 2
    },
    {
      "pos": [
        21,
        3,
        28
      ],
      "state": 1
    },
    {
      "pos": [
        21,
        3,
        29
      ],
      "state": 1
    },
    {
      "pos": [
        22,
        3,
        2
      ],
      "state": 1
    },
    {
      "pos": [
        22,
        3,
        3
      ],
      "state": 1
    },
    {
      "pos": [
        22,
        3,
        4
      ],
      "state": 1
    },
    {
      "pos": [
        22,
        3,
        5
      ],
      "state": 5
    },
    {
      "pos": [
        22,
        3,
        6
      ],
      "state": 6
    },
    {
      "pos": [
        22,
        3,
        7
      ],
      "state": 8
    },
    {
      "pos": [
        22,
        3,
        8
      ],
      "state": 9
    },
    {
      "pos": [
        22,
        3,
        9
      ],
      "state": 9
    },
    {
      "pos": [
        22,
        3,
        10
      ],
      "state": 8
    },
    {
      "pos": [
        22,
        3,
        11
      ],
      "state": 9
    },
    {
      "pos": [
        22,
        3,
        12
      ],
      "state": 9
    },
    {
      "pos": [
        22,
        3,
        13
      ],
      "state": 9
    },
    {
      "pos": [
        22,
        3,
        14
      ],
      "state": 9
    },
    {
      "pos": [
        22,
        3,
        15
      ],
      "state": 8
    },
    {
      "pos": [
        22,
        3,
        16
      ],
      "state": 9
    },
    {
      "pos": [
        22,
        3,
        17
      ],
      "state": 7
    },
    {
      "pos": [
        22,
        3,
        18
      ],
      "state": 7
    },
    {
      "pos": [
        22,
        3,
        19
      ],
      "state": 9
    },
    {
      "pos": [
        22,
        3,
        20
      ],
      "state": 8
    },
    {
      "pos": [
        22,
        3,
        21
      ],
      "state": 9
    },
    {
      "pos": [
        22,
        3,
        22
      ],
      "state": 8
    },
    {
      "pos": [
        22,
        3,
        23
      ],
      "state": 9
    },
    {
      "pos": [
        22,
        3,
        24
      ],
      "state": 4
    },
    {
      "pos": [
        22,
        3,
        25
      ],
      "state": 6
    },
    {
      "pos": [
        22,
        3,
        26
      ],
      "state": 1
    },
    {
      "pos": [
        22,
        3,
        27
      ],
      "state": 1
    },
    {
      "pos": [
        22,
        3,
        28
      ],
      "state": 3
    },
    {
      "pos": [
        23,
        3,
        3
      ],
      "state": 1
    },
    {
      "pos": [
        23,
        3,
        4
      ],
      "state": 2
    },
    {
      "pos": [
        23,
        3,
        5
      ],
      "state": 5
    },
    {
      "pos": [
        23,
        3,
        6
      ],
      "state": 5
    },
    {
      "pos": [
        23,
        3,
        7
      ],
      "state": 4
    },
    {
      "pos": [
        23,
        3,
        8
      ],
      "state": 9
    },
    {
      "pos": [
        23,
        3,
        9
      ],
      "state": 9
    },
    {
      "pos": [
        23,
        3,
        10
      ],
      "state": 8
    },
    {
      "pos": [
        23,
        3,
        11
      ],
      "state": 9
    },
    {
      "pos": [
        23,
        3,
        12
      ],
      "state": 9
    },
    {
      "pos": [
        23,
        3,
        13
      ],
      "state": 7
    },
    {
      "pos": [
        23,
        3,
        14
      ],
      "state": 8
    },
    {
      "pos": [
        23,
        3,
        15
      ],
      "state": 9
    },
    {
      "pos": [
        23,
        3,
        16
      ],
      "state": 8
    },
    {
      "pos": [
        23,
        3,
        17
      ],
      "state": 8
    },
    {
      "pos": [
        23,
        3,
        18
      ],
      "state": 9
    },
    {
      "pos": [
        23,
        3,
        19
      ],
      "state": 8
    },
    {
      "pos": [
        23,
        3,
        20
      ],
      "state": 9
    },
    {
      "pos": [
        23,
        3,
        21
      ],
      "state": 9
    },
    {
      "pos": [
        23,
        3,
        22
      ],
      "state": 7
    },
    {
      "pos": [
        23,
        3,
        23
      ],
      "state": 4
    },
    {
      "pos": [
        23,
        3,
        24
      ],
      "state": 5
    },
    {
      "pos": [
        23,
        3,
        25
      ],
      "state": 5
    },
    {
      "pos": [
        23,
        3,
        26
      ],
      "state": 1
    },
    {
      "pos": [
        23,
        3,
        27
      ],
      "state": 1
    },
    {
      "pos": [
        24,
        3,
        3
      ],
      "state": 2
    },
    {
      "pos": [
        24,
        3,
        4
      ],
      "state": 1
    },
    {
      "pos": [
        24,
        3,
        5
      ],
      "state": 9
    },
    {
      "pos": [
        24,
        3,
        6
      ],
      "state": 4
    },
    {
      "pos": [
        24,
        3,
        7
      ],
      "state": 5
    },
    {
      "pos": [
        24,
        3,
        8
      ],
      "state": 4
    },
    {
      "pos": [
        24,
        3,
        9
      ],
      "state": 8
    },
    {
      "pos": [
        24,
        3,
        10
      ],
      "state": 8
    },
    {
      "pos": [
        24,
        3,
        11
      ],
      "state": 9
    },
    {
      "pos": [
        24,
        3,
        12
      ],
      "state": 7
    },
    {
      "pos": [
        24,
        3,
        13
      ],
      "state": 9
    },
    {
      "pos": [
        24,
        3,
        14
      ],
      "state": 7
    },
    {
      "pos": [
        24,
        3,
        15
      ],
      "state": 9
    },
    {
      "pos": [
        24,
        3,
        16
      ],
      "state": 7
    },
    {
      "pos": [
        24,
        3,
        17
      ],
      "state": 8
    },
    {
      "pos": [
        24,
        3,
        18
      ],
      "state": 8
    },
    {
      "pos": [
        24,
        3,
        19
      ],
      "state": 8
    },
    {
      "pos": [
        24,
        3,
        20
      ],
      "state": 9
    },
    {
      "pos": [
        24,
        3,
        21
      ],
      "state": 7
    },
    {
      "pos": [
        24,
        3,
        22
      ],
      "state": 6
    },
    {
      "pos": [
        24,
        3,
        23
      ],
      "state": 4
    },
    {
      "pos": [
        24,
        3,
        24
      ],
      "state": 6
    },
    {
      "pos": [
        24,
        3,
        25
      ],
      "state": 8
    },
    {
      "pos": [
        24,
        3,
        26
      ],
      "state": 1
    },
    {
      "pos": [
        24,
        3,
        27
      ],
      "state": 1
    },
    {
      "pos": [
        25,
        3,
        4
      ],
      "state": 1
    },
    {
      "pos": [
        25,
        3,
        5
      ],
      "state": 7
    },
    {
      "pos": [
        25,
        3,
        6
      ],
      "state": 7
    },
    {
      "pos": [
        25,
        3,
        7
      ],
      "state": 4
    },
    {
      "pos": [
        25,
        3,
        8
      ],
      "state": 4
    },
    {
      "pos": [
        25,
        3,
        9
      ],
      "state": 6
    },
    {
      "pos": [
        25,
        3,
        10
      ],
      "state": 4
    },
    {
      "pos": [
        25,
        3,
        11
      ],
      "state": 8
    },
    {
      "pos": [
        25,
        3,
        12
      ],
      "state": 7
    },
    {
      "pos": [
        25,
        3,
        13
      ],
      "state": 9
    },
    {
      "pos": [
        25,
        3,
        14
      ],
      "state": 8
    },
    {
      "pos": [
        25,
        3,
        15
      ],
      "state": 8
    },
    {
      "pos": [
        25,
        3,
        16
      ],
      "state": 8
    },
    {
      "pos": [
        25,
        3,
        17
      ],
      "state": 7
    },
    {
      "pos": [
        25,
        3,
        18
      ],
      "state": 9
    },
    {
      "pos": [
        25,
        3,
        19
      ],
      "state": 8
    },
    {
      "pos": [
        25,
        3,
        20
      ],
      "state": 4
    },
    {
      "pos": [
        25,
        3,
        21
      ],
      "state": 4
    },
    {
      "pos": [
        25,
        3,
        22
      ],
      "state": 4
    },
    {
      "pos": [
        25,
        3,
        23
      ],
      "state": 4
    },
    {
      "pos": [
        25,
        3,
        24
      ],
      "state": 9
    },
    {
      "pos": [
        25,
        3,
        25
      ],
      "state": 7
    },
    {
      "pos": [
        25,
        3,
        26
      ],
      "state": 1
    },
    {
      "pos": [
        26,
        3,
        5
      ],
      "state": 1
    },
    {
      "pos": [
        26,
        3,
        6
      ],
      "state": 2
    },
    {
      "pos": [
        26,
        3,
        7
      ],
      "state": 1
    },
    {
      "pos": [
        26,
        3,
        8
      ],
      "state": 2
    },
    {
      "pos": [
        26,
        3,
        9
      ],
      "state": 5
    },
    {
      "pos": [
        26,
        3,
        10
      ],
      "state": 4
    },
    {
      "pos": [
        26,
        3,
        11
      ],
      "state": 4
    },
    {
      "pos": [
        26,
        3,
        12
      ],
      "state": 6
    },
    {
      "pos": [
        26,
        3,
        13
      ],
      "state": 4
    },
    {
      "pos": [
        26,
        3,
        14
      ],
      "state": 4
    },
    {
      "pos": [
        26,
        3,
        15
      ],
      "state": 4
    },
    {
      "pos": [
        26,
        3,
        16
      ],
      "state": 4
    },
    {
      "pos": [
        26,
        3,
        17
      ],
      "state": 5
    },
    {
      "pos": [
        26,
        3,
        18
      ],
      "state": 4
    },
    {
      "pos": [
        26,
        3,
        19
      ],
      "state": 6
    },
    {
      "pos": [
        26,
        3,
        20
      ],
      "state": 5
    },
    {
      "pos": [
        26,
        3,
        21
      ],
      "state": 6
    },
    {
      "pos": [
        26,
        3,
        22
      ],
      "state": 3
    },
    {
      "pos": [
        26,
        3,
        23
      ],
      "state": 1
    },
    {
      "pos": [
        26,
        3,
        24
      ],
      "state": 2
    },
    {
      "pos": [
        26,
        3,
        25
      ],
      "state": 1
    },
    {
      "pos": [
        27,
        3,
        6
      ],
      "state": 1
    },
    {
      "pos": [
        27,
        3,
        7
      ],
      "state": 1
    },
    {
      "pos": [
        27,
        3,
        8
      ],
      "state": 1
    },
    {
      "pos": [
        27,
        3,
        9
      ],
      "state": 2
    },
    {
      "pos": [
        27,
        3,
        10
      ],
      "state": 5
    },
    {
      "pos": [
        27,
        3,
        11
      ],
      "state": 6
    },
    {
      "pos": [
        27,
        3,
        12
      ],
      "state": 6
    },
    {
      "pos": [
        27,
        3,
        13
      ],
      "state": 6
    },
    {
      "pos": [
        27,
        3,
        14
      ],
      "state": 5
    },
    {
      "pos": [
        27,
        3,
        15
      ],
      "state": 5
    },
    {
      "pos": [
        27,
        3,
        16
      ],
      "state": 5
    },
    {
      "pos": [
        27,
        3,
        17
      ],
      "state": 4
    },
    {
      "pos": [
        27,
        3,
        18
      ],
      "state": 6
    },
    {
      "pos": [
        27,
        3,
        19
      ],
      "state": 5
    },
    {
      "pos": [
        27,
        3,
        20
      ],
      "state": 5
    },
    {
      "pos": [
        27,
        3,
        21
      ],
      "state": 1
    },
    {
      "pos": [
        27,
        3,
        22
      ],
      "state": 3
    },
    {
      "pos": [
        27,
        3,
        23
      ],
      "state": 1
    },
    {
      "pos": [
        27,
        3,
        24
      ],
      "state": 1
    },
    {
      "pos": [
        28,
        3,
        8
      ],
      "state": 1
    },
    {
      "pos": [
        28,
        3,
        9
      ],
      "state": 1
    },
    {
      "pos": [
        28,
        3,
        10
      ],
      "state": 1
    },
    {
      "pos": [
        28,
        3,
        11
      ],
      "state": 1
    },
    {
      "pos": [
        28,
        3,
        12
      ],
      "state": 2
    },
    {
      "pos": [
        28,
        3,
        13
      ],
      "state": 1
    },
    {
      "pos": [
        28,
        3,
        14
      ],
      "state": 1
    },
    {
      "pos": [
        28,
        3,
        15
      ],
      "state": 5
    },
    {
      "pos": [
        28,
        3,
        16
      ],
      "state": 1
    },
    {
      "pos": [
        28,
        3,
        17
      ],
      "state": 1
    },
    {
      "pos": [
        28,
        3,
        18
      ],
      "state": 2
    },
    {
      "pos": [
        28,
        3,
        19
      ],
      "state": 1
    },
    {
      "pos": [
        28,
        3,
        20
      ],
      "state": 1
    },
    {
      "pos": [
        28,
        3,
        21
      ],
      "state": 1
    },
    {
      "pos": [
        28,
        3,
        22
      ],
      "state": 1
    },
    {
      "pos": [
        29,
        3,
        9
      ],
      "state": 1
    },
    {
      "pos": [
        29,
        3,
        10
      ],
      "state": 1
    },
    {
      "pos": [
        29,
        3,
        11
      ],
      "state": 3
    },
    {
      "pos": [
        29,
        3,
        12
      ],
      "state": 1
    },
    {
      "pos": [
        29,
        3,
        13
      ],
      "state": 1
    },
    {
      "pos": [
        29,
        3,
        14
      ],
      "state": 1
    },
    {
      "pos": [
        29,
        3,
        15
      ],
      "state": 1
    },
    {
      "pos": [
        29,
        3,
        16
      ],
      "state": 1
    },
    {
      "pos": [
        29,
        3,
        17
      ],
      "state": 1
    },
    {
      "pos": [
        29,
        3,
        18
      ],
      "state": 2
    },
    {
      "pos": [
        29,
        3,
        19
      ],
      "state": 3
    },
    {
      "pos": [
        29,
        3,
        20
      ],
      "state": 1
    },
    {
      "pos": [
        29,
        3,
        21
      ],
      "state": 1
    },
    {
      "pos": [
        30,
        3,
        13
      ],
      "state": 3
    },
    {
      "pos": [
        30,
        3,
        14
      ],
      "state": 1
    },
    {
      "pos": [
        30,
        3,
        15
      ],
      "state": 2
    },
    {
      "pos": [
        30,
        3,
        16
      ],
      "state": 2
    },
    {
      "pos": [
        30,
        3,
        17
      ],
      "state": 1
    },
    {
      "pos": [
        1,
        4,
        13
      ],
      "state": 12
    },
    {
      "pos": [
        1,
        4,
        14
      ],
      "state": 13
    },
    {
      "pos": [
        1,
        4,
        15
      ],
      "state": 13
    },
    {
      "pos": [
        1,
        4,
        16
      ],
      "state": 13
    },
    {
      "pos": [
        1,
        4,
        17
      ],
      "state": 12
    },
    {
      "pos": [
        2,
        4,
        15
      ],
      "state": 14,
      "nbt": {
        "id": "minecraft:chest",
        "LootTable": "darkspawn:chests/druid_shrine"
      }
    },
    {
      "pos": [
        3,
        4,
        8
      ],
      "state": 7
    },
    {
      "pos": [
        3,
        4,
        9
      ],
      "state": 7
    },
    {
      "pos": [
        3,
        4,
        22
      ],
      "state": 7
    },
    {
      "pos": [
        3,
        4,
        23
      ],
      "state": 7
    },
    {
      "pos": [
        4,
        4,
        8
      ],
      "state": 7
    },
    {
      "pos": [
        4,
        4,
        9
      ],
      "state": 7
    },
    {
      "pos": [
        4,
        4,
        22
      ],
      "state": 7
    },
    {
      "pos": [
        4,
        4,
        23
      ],
      "state": 7
    },
    {
      "pos": [
        8,
        4,
        3
      ],
      "state": 7
    },
    {
      "pos": [
        8,
        4,
        4
      ],
      "state": 7
    },
    {
      "pos": [
        8,
        4,
        27
      ],
      "state": 7
    },
    {
      "pos": [
        8,
        4,
        28
      ],
      "state": 7
    },
    {
      "pos": [
        9,
        4,
        3
      ],
      "state": 7
    },
    {
      "pos": [
        9,
        4,
        4
      ],
      "state": 7
    },
    {
      "pos": [
        9,
        4,
        27
      ],
      "state": 7
    },
    {
      "pos": [
        9,
        4,
        28
      ],
      "state": 7
    },
    {
      "pos": [
        12,
        4,
        1
      ],
      "state": 8
    },
    {
      "pos": [
        12,
        4,
        2
      ],
      "state": 8
    },
    {
      "pos": [
        13,
        4,
        1
      ],
      "state": 8
    },
    {
      "pos": [
        13,
        4,
        2
      ],
      "state": 8
    },
    {
      "pos": [
        18,
        4,
        1
      ],
      "state": 7
    },
    {
      "pos": [
        18,
        4,
        2
      ],
      "state": 7
    },
    {
      "pos": [
        19,
        4,
        1
      ],
      "state": 7
    },
    {
      "pos": [
        19,
        4,
        2
      ],
      "state": 7
    },
    {
      "pos": [
        22,
        4,
        3
      ],
      "state": 7
    },
    {
      "pos": [
        22,
        4,
        4
      ],
      "state": 7
    },
    {
      "pos": [
        22,
        4,
        27
      ],
      "state": 7
    },
    {
      "pos": [
        22,
        4,
        28
      ],
      "state": 7
    },
    {
      "pos": [
        23,
        4,
        3
      ],
      "state": 7
    },
    {
      "pos": [
        23,
        4,
        4
      ],
      "state": 7
    },
    {
      "pos": [
        23,
        4,
        27
      ],
      "state": 7
    },
    {
      "pos": [
        23,
        4,
        28
      ],
      "state": 7
    },
    {
      "pos": [
        25,
        4,
        26
      ],
      "state": 15
    },
    {
      "pos": [
        26,
        4,
        2
      ],
      "state": 15
    },
    {
      "pos": [
        26,
        4,
        26
      ],
      "state": 15
    },
    {
      "pos": [
        27,
        4,
        2
      ],
      "state": 15
    },
    {
      "pos": [
        27,
        4,
        8
      ],
      "state": 7
    },
    {
      "pos": [
        27,
        4,
        9
      ],
      "state": 7
    },
    {
      "pos": [
        27,
        4,
        22
      ],
      "state": 7
    },
    {
      "pos": [
        27,
        4,
        23
      ],
      "state": 7
    },
    {
      "pos": [
        27,
        4,
        26
      ],
      "state": 15
    },
    {
      "pos": [
        28,
        4,
        2
      ],
      "state": 15
    },
    {
      "pos": [
        28,
        4,
        8
      ],
      "state": 7
    },
    {
      "pos": [
        28,
        4,
        9
      ],
      "state": 7
    },
    {
      "pos": [
        28,
        4,
        22
      ],
      "state": 7
    },
    {
      "pos": [
        28,
        4,
        23
      ],
      "state": 7
    },
    {
      "pos": [
        28,
        4,
        26
      ],
      "state": 15
    },
    {
      "pos": [
        29,
        4,
        2
      ],
      "state": 15
    },
    {
      "pos": [
        1,
        5,
        13
      ],
      "state": 12
    },
    {
      "pos": [
        1,
        5,
        17
      ],
      "state": 12
    },
    {
      "pos": [
        3,
        5,
        8
      ],
      "state": 7
    },
    {
      "pos": [
        3,
        5,
        9
      ],
      "state": 7
    },
    {
      "pos": [
        3,
        5,
        22
      ],
      "state": 7
    },
    {
      "pos": [
        3,
        5,
        23
      ],
      "state": 7
    },
    {
      "pos": [
        4,
        5,
        8
      ],
      "state": 7
    },
    {
      "pos": [
        4,
        5,
        9
      ],
      "state": 7
    },
    {
      "pos": [
        4,
        5,
        22
      ],
      "state": 7
    },
    {
      "pos": [
        4,
        5,
        23
      ],
      "state": 7
    },
    {
      "pos": [
        8,
        5,
        3
      ],
      "state": 7
    },
    {
      "pos": [
        8,
        5,
        4
      ],
      "state": 7
    },
    {
      "pos": [
        8,
        5,
        27
      ],
      "state": 7
    },
    {
      "pos": [
        8,
        5,
        28
      ],
      "state": 7
    },
    {
      "pos": [
        9,
        5,
        3
      ],
      "state": 7
    },
    {
      "pos": [
        9,
        5,
        4
      ],
      "state": 7
    },
    {
      "pos": [
        9,
        5,
        27
      ],
      "state": 7
    },
    {
      "pos": [
        9,
        5,
        28
      ],
      "state": 7
    },
    {
      "pos": [
        12,
        5,
        1
      ],
      "state": 8
    },
    {
      "pos": [
        12,
        5,
        2
      ],
      "state": 8
    },
    {
      "pos": [
        13,
        5,
        1
      ],
      "state": 8
    },
    {
      "pos": [
        13,
        5,
        2
      ],
      "state": 8
    },
    {
      "pos": [
        18,
        5,
        1
      ],
      "state": 7
    },
    {
      "pos": [
        18,
        5,
        2
      ],
      "state": 7
    },
    {
      "pos": [
        19,
        5,
        1
      ],
      "state": 7
    },
    {
      "pos": [
        19,
        5,
        2
      ],
      "state": 7
    },
    {
      "pos": [
        22,
        5,
        3
      ],
      "state": 7
    },
    {
      "pos": [
        22,
        5,
        4
      ],
      "state": 7
    },
    {
      "pos": [
        22,
        5,
        27
      ],
      "state": 7
    },
    {
      "pos": [
        22,
        5,
        28
      ],
      "state": 7
    },
    {
      "pos": [
        23,
        5,
        3
      ],
      "state": 7
    },
    {
      "pos": [
        23,
        5,
        4
      ],
      "state": 7
    },
    {
      "pos": [
        23,
        5,
        27
      ],
      "state": 7
    },
    {
      "pos": [
        23,
        5,
        28
      ],
      "state": 7
    },
    {
      "pos": [
        27,
        5,
        8
      ],
      "state": 7
    },
    {
      "pos": [
        27,
        5,
        9
      ],
      "state": 7
    },
    {
      "pos": [
        27,
        5,
        22
      ],
      "state": 7
    },
    {
      "pos": [
        27,
        5,
        23
      ],
      "state": 7
    },
    {
      "pos": [
        28,
        5,
        8
      ],
      "state": 7
    },
    {
      "pos": [
        28,
        5,
        9
      ],
      "state": 7
    },
    {
      "pos": [
        28,
        5,
        22
      ],
      "state": 7
    },
    {
      "pos": [
        28,
        5,
        23
      ],
      "state": 7
    },
    {
      "pos": [
        1,
        6,
        13
      ],
      "state": 12
    },
    {
      "pos": [
        1,
        6,
        17
      ],
      "state": 12
    },
    {
      "pos": [
        3,
        6,
        8
      ],
      "state": 7
    },
    {
      "pos": [
        3,
        6,
        9
      ],
      "state": 7
    },
    {
      "pos": [
        3,
        6,
        22
      ],
      "state": 7
    },
    {
      "pos": [
        3,
        6,
        23
      ],
      "state": 7
    },
    {
      "pos": [
        4,
        6,
        8
      ],
      "state": 7
    },
    {
      "pos": [
        4,
        6,
        9
      ],
      "state": 7
    },
    {
      "pos": [
        4,
        6,
        22
      ],
      "state": 7
    },
    {
      "pos": [
        4,
        6,
        23
      ],
      "state": 7
    },
    {
      "pos": [
        8,
        6,
        3
      ],
      "state": 7
    },
    {
      "pos": [
        8,
        6,
        4
      ],
      "state": 7
    },
    {
      "pos": [
        8,
        6,
        27
      ],
      "state": 7
    },
    {
      "pos": [
        8,
        6,
        28
      ],
      "state": 7
    },
    {
      "pos": [
        9,
        6,
        3
      ],
      "state": 7
    },
    {
      "pos": [
        9,
        6,
        4
      ],
      "state": 7
    },
    {
      "pos": [
        9,
        6,
        27
      ],
      "state": 7
    },
    {
      "pos": [
        9,
        6,
        28
      ],
      "state": 7
    },
    {
      "pos": [
        12,
        6,
        1
      ],
      "state": 8
    },
    {
      "pos": [
        12,
        6,
        2
      ],
      "state": 8
    },
    {
      "pos": [
        13,
        6,
        1
      ],
      "state": 8
    },
    {
      "pos": [
        13,
        6,
        2
      ],
      "state": 8
    },
    {
      "pos": [
        18,
        6,
        1
      ],
      "state": 7
    },
    {
      "pos": [
        18,
        6,
        2
      ],
      "state": 7
    },
    {
      "pos": [
        19,
        6,
        1
      ],
      "state": 7
    },
    {
      "pos": [
        19,
        6,
        2
      ],
      "state": 7
    },
    {
      "pos": [
        22,
        6,
        3
      ],
      "state": 7
    },
    {
      "pos": [
        22,
        6,
        4
      ],
      "state": 7
    },
    {
      "pos": [
        22,
        6,
        27
      ],
      "state": 7
    },
    {
      "pos": [
        22,
        6,
        28
      ],
      "state": 7
    },
    {
      "pos": [
        23,
        6,
        3
      ],
      "state": 7
    },
    {
      "pos": [
        23,
        6,
        4
      ],
      "state": 7
    },
    {
      "pos": [
        23,
        6,
        27
      ],
      "state": 7
    },
    {
      "pos": [
        23,
        6,
        28
      ],
      "state": 7
    },
    {
      "pos": [
        27,
        6,
        8
      ],
      "state": 7
    },
    {
      "pos": [
        27,
        6,
        9
      ],
      "state": 7
    },
    {
      "pos": [
        27,
        6,
        22
      ],
      "state": 7
    },
    {
      "pos": [
        27,
        6,
        23
      ],
      "state": 7
    },
    {
      "pos": [
        28,
        6,
        8
      ],
      "state": 7
    },
    {
      "pos": [
        28,
        6,
        9
      ],
      "state": 7
    },
    {
      "pos": [
        28,
        6,
        22
      ],
      "state": 7
    },
    {
      "pos": [
        28,
        6,
        23
      ],
      "state": 7
    },
    {
      "pos": [
        1,
        7,
        13
      ],
      "state": 12
    },
    {
      "pos": [
        1,
        7,
        17
      ],
      "state": 12
    },
    {
      "pos": [
        3,
        7,
        8
      ],
      "state": 10
    },
    {
      "pos": [
        3,
        7,
        22
      ],
      "state": 7
    },
    {
      "pos": [
        3,
        7,
        23
      ],
      "state": 7
    },
    {
      "pos": [
        4,
        7,
        9
      ],
      "state": 2
    },
    {
      "pos": [
        4,
        7,
        22
      ],
      "state": 7
    },
    {
      "pos": [
        4,
        7,
        23
      ],
      "state": 7
    },
    {
      "pos": [
        8,
        7,
        3
      ],
      "state": 7
    },
    {
      "pos": [
        8,
        7,
        4
      ],
      "state": 7
    },
    {
      "pos": [
        8,
        7,
        27
      ],
      "state": 7
    },
    {
      "pos": [
        8,
        7,
        28
      ],
      "state": 7
    },
    {
      "pos": [
        9,
        7,
        3
      ],
      "state": 7
    },
    {
      "pos": [
        9,
        7,
        4
      ],
      "state": 7
    },
    {
      "pos": [
        9,
        7,
        27
      ],
      "state": 7
    },
    {
      "pos": [
        9,
        7,
        28
      ],
      "state": 7
    },
    {
      "pos": [
        12,
        7,
        1
      ],
      "state": 8
    },
    {
      "pos": [
        12,
        7,
        2
      ],
      "state": 8
    },
    {
      "pos": [
        13,
        7,
        1
      ],
      "state": 8
    },
    {
      "pos": [
        13,
        7,
        2
      ],
      "state": 8
    },
    {
      "pos": [
        18,
        7,
        1
      ],
      "state": 7
    },
    {
      "pos": [
        18,
        7,
        2
      ],
      "state": 7
    },
    {
      "pos": [
        19,
        7,
        1
      ],
      "state": 7
    },
    {
      "pos": [
        19,
        7,
        2
      ],
      "state": 7
    },
    {
      "pos": [
        22,
        7,
        3
      ],
      "state": 7
    },
    {
      "pos": [
        22,
        7,
        4
      ],
      "state": 7
    },
    {
      "pos": [
        22,
        7,
        27
      ],
      "state": 7
    },
    {
      "pos": [
        22,
        7,
        28
      ],
      "state": 7
    },
    {
      "pos": [
        23,
        7,
        3
      ],
      "state": 7
    },
    {
      "pos": [
        23,
        7,
        4
      ],
      "state": 7
    },
    {
      "pos": [
        23,
        7,
        27
      ],
      "state": 7
    },
    {
      "pos": [
        23,
        7,
        28
      ],
      "state": 7
    },
    {
      "pos": [
        27,
        7,
        8
      ],
      "state": 10
    },
    {
      "pos": [
        27,
        7,
        22
      ],
      "state": 7
    },
    {
      "pos": [
        27,
        7,
        23
      ],
      "state": 7
    },
    {
      "pos": [
        28,
        7,
        9
      ],
      "state": 2
    },
    {
      "pos": [
        28,
        7,
        22
      ],
      "state": 7
    },
    {
      "pos": [
        28,
        7,
        23
      ],
      "state": 7
    },
    {
      "pos": [
        0,
        8,
        12
      ],
      "state": 16
    },
    {
      "pos": [
        0,
        8,
        13
      ],
      "state": 16
    },
    {
      "pos": [
        0,
        8,
        14
      ],
      "state": 16
    },
    {
      "pos": [
        0,
        8,
        15
      ],
      "state": 16
    },
    {
      "pos": [
        0,
        8,
        16
      ],
      "state": 16
    },
    {
      "pos": [
        0,
        8,
        17
      ],
      "state": 16
    },
    {
      "pos": [
        0,
        8,
        18
      ],
      "state": 16
    },
    {
      "pos": [
        1,
        8,
        12
      ],
      "state": 16
    },
    {
      "pos": [
        1,
        8,
        13
      ],
      "state": 16
    },
    {
      "pos": [
        1,
        8,
        14
      ],
      "state": 16
    },
    {
      "pos": [
        1,
        8,
        15
      ],
      "state": 16
    },
    {
      "pos": [
        1,
        8,
        16
      ],
      "state": 16
    },
    {
      "pos": [
        1,
        8,
        17
      ],
      "state": 16
    },
    {
      "pos": [
        1,
        8,
        18
      ],
      "state": 16
    },
    {
      "pos": [
        2,
        8,
        12
      ],
      "state": 16
    },
    {
      "pos": [
        2,
        8,
        13
      ],
      "state": 16
    },
    {
      "pos": [
        2,
        8,
        14
      ],
      "state": 16
    },
    {
      "pos": [
        2,
        8,
        15
      ],
      "state": 16
    },
    {
      "pos": [
        2,
        8,
        16
      ],
      "state": 16
    },
    {
      "pos": [
        2,
        8,
        17
      ],
      "state": 16
    },
    {
      "pos": [
        2,
        8,
        18
      ],
      "state": 16
    },
    {
      "pos": [
        3,
        8,
        12
      ],
      "state": 16
    },
    {
      "pos": [
        3,
        8,
        13
      ],
      "state": 16
    },
    {
      "pos": [
        3,
        8,
        14
      ],
      "state": 16
    },
    {
      "pos": [
        3,
        8,
        15
      ],
      "state": 16
    },
    {
      "pos": [
        3,
        8,
        16
      ],
      "state": 16
    },
    {
      "pos": [
        3,
        8,
        17
      ],
      "state": 16
    },
    {
      "pos": [
        3,
        8,
        18
      ],
      "state": 16
    },
    {
      "pos": [
        3,
        8,
        22
      ],
      "state": 10
    },
    {
      "pos": [
        8,
        8,
        3
      ],
      "state": 7
    },
    {
      "pos": [
        8,
        8,
        4
      ],
      "state": 7
    },
    {
      "pos": [
        8,
        8,
        27
      ],
      "state": 7
    },
    {
      "pos": [
        8,
        8,
        28
      ],
      "state": 7
    },
    {
      "pos": [
        9,
        8,
        3
      ],
      "state": 7
    },
    {
      "pos": [
        9,
        8,
        4
      ],
      "state": 7
    },
    {
      "pos": [
        9,
        8,
        27
      ],
      "state": 7
    },
    {
      "pos": [
        9,
        8,
        28
      ],
      "state": 7
    },
    {
      "pos": [
        12,
        8,
        1
      ],
      "state": 8
    },
    {
      "pos": [
        12,
        8,
        2
      ],
      "state": 8
    },
    {
      "pos": [
        13,
        8,
        1
      ],
      "state": 8
    },
    {
      "pos": [
        13,
        8,
        2
      ],
      "state": 8
    },
    {
      "pos": [
        18,
        8,
        1
      ],
      "state": 7
    },
    {
      "pos": [
        18,
        8,
        2
      ],
      "state": 7
    },
    {
      "pos": [
        19,
        8,
        1
      ],
      "state": 7
    },
    {
      "pos": [
        19,
        8,
        2
      ],
      "state": 7
    },
    {
      "pos": [
        22,
        8,
        3
      ],
      "state": 7
    },
    {
      "pos": [
        22,
        8,
        4
      ],
      "state": 7
    },
    {
      "pos": [
        22,
        8,
        27
      ],
      "state": 7
    },
    {
      "pos": [
        22,
        8,
        28
      ],
      "state": 7
    },
    {
      "pos": [
        23,
        8,
        3
      ],
      "state": 7
    },
    {
      "pos": [
        23,
        8,
        4
      ],
      "state": 7
    },
    {
      "pos": [
        23,
        8,
        27
      ],
      "state": 7
    },
    {
      "pos": [
        23,
        8,
        28
      ],
      "state": 7
    },
    {
      "pos": [
        27,
        8,
        22
      ],
      "state": 10
    },
    {
      "pos": [
        8,
        9,
        3
      ],
      "state": 10
    },
    {
      "pos": [
        8,
        9,
        27
      ],
      "state": 10
    },
    {
      "pos": [
        9,
        9,
        4
      ],
      "state": 2
    },
    {
      "pos": [
        9,
        9,
        28
      ],
      "state": 2
    },
    {
      "pos": [
        12,
        9,
        1
      ],
      "state": 8
    },
    {
      "pos": [
        12,
        9,
        2
      ],
      "state": 8
    },
    {
      "pos": [
        13,
        9,
        1
      ],
      "state": 8
    },
    {
      "pos": [
        13,
        9,
        2
      ],
      "state": 8
    },
    {
      "pos": [
        22,
        9,
        3
      ],
      "state": 7
    },
    {
      "pos": [
        22,
        9,
        4
      ],
      "state": 7
    },
    {
      "pos": [
        22,
        9,
        27
      ],
      "state": 7
    },
    {
      "pos": [
        22,
        9,
        28
      ],
      "state": 7
    },
    {
      "pos": [
        23,
        9,
        3
      ],
      "state": 7
    },
    {
      "pos": [
        23,
        9,
        4
      ],
      "state": 7
    },
    {
      "pos": [
        23,
        9,
        27
      ],
      "state": 7
    },
    {
      "pos": [
        23,
        9,
        28
      ],
      "state": 7
    },
    {
      "pos": [
        13,
        10,
        1
      ],
      "state": 10
    },
    {
      "pos": [
        13,
        10,
        2
      ],
      "state": 10
    },
    {
      "pos": [
        14,
        10,
        1
      ],
      "state": 10
    },
    {
      "pos": [
        14,
        10,
        2
      ],
      "state": 10
    },
    {
      "pos": [
        15,
        10,
        1
      ],
      "state": 10
    },
    {
      "pos": [
        15,
        10,
        2
      ],
      "state": 10
    },
    {
      "pos": [
        16,
        10,
        1
      ],
      "state": 10
    },
    {
      "pos": [
        16,
        10,
        2
      ],
      "state": 10
    },
    {
      "pos": [
        17,
        10,
        1
      ],
      "state": 10
    },
    {
      "pos": [
        17,
        10,
        2
      ],
      "state": 10
    },
    {
      "pos": [
        22,
        10,
        3
      ],
      "state": 10
    },
    {
      "pos": [
        22,
        10,
        27
      ],
      "state": 10
    }
  ]
}
