{
  "size": [
    25,
    48,
    25
  ],
  "anchor": [
    12,
    3,
    12
  ],
  "chest": [
    12,
    4,
    2
  ],
  "palette": [
    {
      "Name": "minecraft:dirt"
    },
    {
      "Name": "minecraft:coarse_dirt"
    },
    {
      "Name": "minecraft:grass_block"
    },
    {
      "Name": "minecraft:moss_block"
    },
    {
      "Name": "minecraft:dirt_path"
    },
    {
      "Name": "minecraft:gravel"
    },
    {
      "Name": "minecraft:bone_block",
      "Properties": {
        "axis": "y"
      }
    },
    {
      "Name": "minecraft:cobblestone"
    },
    {
      "Name": "minecraft:air"
    },
    {
      "Name": "minecraft:spruce_log",
      "Properties": {
        "axis": "x"
      }
    },
    {
      "Name": "minecraft:stripped_spruce_log",
      "Properties": {
        "axis": "y"
      }
    },
    {
      "Name": "minecraft:spruce_planks"
    },
    {
      "Name": "minecraft:spruce_log",
      "Properties": {
        "axis": "y"
      }
    },
    {
      "Name": "minecraft:brown_wool"
    },
    {
      "Name": "minecraft:chest",
      "Properties": {
        "facing": "south",
        "type": "single",
        "waterlogged": "false"
      }
    },
    {
      "Name": "minecraft:gray_wool"
    },
    {
      "Name": "minecraft:campfire",
      "Properties": {
        "facing": "north",
        "lit": "false",
        "signal_fire": "false",
        "waterlogged": "false"
      }
    },
    {
      "Name": "minecraft:spruce_fence",
      "Properties": {
        "north": "true",
        "south": "true",
        "east": "false",
        "west": "false",
        "waterlogged": "false"
      }
    },
    {
      "Name": "minecraft:spruce_trapdoor",
      "Properties": {
        "facing": "west",
        "half": "bottom",
        "open": "true",
        "powered": "false",
        "waterlogged": "false"
      }
    },
    {
      "Name": "minecraft:hay_block",
      "Properties": {
        "axis": "y"
      }
    },
    {
      "Name": "minecraft:spruce_trapdoor",
      "Properties": {
        "facing": "east",
        "half": "bottom",
        "open": "true",
        "powered": "false",
        "waterlogged": "false"
      }
    },
    {
      "Name": "minecraft:spruce_slab",
      "Properties": {
        "type": "bottom",
        "waterlogged": "false"
      }
    }
  ],
  "blocks": [
    {
      "pos": [
        0,
        3,
        10
      ],
      "state": 1
    },
    {
      "pos": [
        0,
        3,
        11
      ],
      "state": 2
    },
    {
      "pos": [
        0,
        3,
        12
      ],
      "state": 2
    },
    {
      "pos": [
        0,
        3,
        13
      ],
      "state": 1
    },
    {
      "pos": [
        0,
        3,
        14
      ],
      "state": 2
    },
    {
      "pos": [
        1,
        3,
        7
      ],
      "state": 2
    },
    {
      "pos": [
        1,
        3,
        8
      ],
      "state": 2
    },
    {
      "pos": [
        1,
        3,
        9
      ],
      "state": 1
    },
    {
      "pos": [
        1,
        3,
        10
      ],
      "state": 2
    },
    {
      "pos": [
        1,
        3,
        11
      ],
      "state": 2
    },
    {
      "pos": [
        1,
        3,
        12
      ],
      "state": 1
    },
    {
      "pos": [
        1,
        3,
        13
      ],
      "state": 2
    },
    {
      "pos": [
        1,
        3,
        14
      ],
      "state": 3
    },
    {
      "pos": [
        1,
        3,
        15
      ],
      "state": 3
    },
    {
      "pos": [
        1,
        3,
        16
      ],
      "state": 2
    },
    {
      "pos": [
        1,
        3,
        17
      ],
      "state": 2
    },
    {
      "pos": [
        2,
        3,
        5
      ],
      "state": 3
    },
    {
      "pos": [
        2,
        3,
        6
      ],
      "state": 2
    },
    {
      "pos": [
        2,
        3,
        7
      ],
      "state": 1
    },
    {
      "pos": [
        2,
        3,
        8
      ],
      "state": 2
    },
    {
      "pos": [
        2,
        3,
        9
      ],
      "state": 2
    },
    {
      "pos": [
        2,
        3,
        10
      ],
      "state": 2
    },
    {
      "pos": [
        2,
        3,
        11
      ],
      "state": 1
    },
    {
      "pos": [
        2,
        3,
        12
      ],
      "state": 2
    },
    {
      "pos": [
        2,
        3,
        13
      ],
      "state": 2
    },
    {
      "pos": [
        2,
        3,
        14
      ],
      "state": 2
    },
    {
      "pos": [
        2,
        3,
        15
      ],
      "state": 2
    },
    {
      "pos": [
        2,
        3,
        16
      ],
      "state": 2
    },
    {
      "pos": [
        2,
        3,
        17
      ],
      "state": 2
    },
    {
      "pos": [
        2,
        3,
        18
      ],
      "state": 2
    },
    {
      "pos": [
        2,
        3,
        19
      ],
      "state": 2
    },
    {
      "pos": [
        3,
        3,
        4
      ],
      "state": 2
    },
    {
      "pos": [
        3,
        3,
        5
      ],
      "state": 2
    },
    {
      "pos": [
        3,
        3,
        6
      ],
      "state": 2
    },
    {
      "pos": [
        3,
        3,
        7
      ],
      "state": 2
    },
    {
      "pos": [
        3,
        3,
        8
      ],
      "state": 2
    },
    {
      "pos": [
        3,
        3,
        9
      ],
      "state": 2
    },
    {
      "pos": [
        3,
        3,
        10
      ],
      "state": 2
    },
    {
      "pos": [
        3,
        3,
        11
      ],
      "state": 2
    },
    {
      "pos": [
        3,
        3,
        12
      ],
      "state": 2
    },
    {
      "pos": [
        3,
        3,
        13
      ],
      "state": 2
    },
    {
      "pos": [
        3,
        3,
        14
      ],
      "state": 3
    },
    {
      "pos": [
        3,
        3,
        15
      ],
      "state": 2
    },
    {
      "pos": [
        3,
        3,
        16
      ],
      "state": 2
    },
    {
      "pos": [
        3,
        3,
        17
      ],
      "state": 2
    },
    {
      "pos": [
        3,
        3,
        18
      ],
      "state": 3
    },
    {
      "pos": [
        3,
        3,
        19
      ],
      "state": 2
    },
    {
      "pos": [
        3,
        3,
        20
      ],
      "state": 2
    },
    {
      "pos": [
        4,
        3,
        3
      ],
      "state": 2
    },
    {
      "pos": [
        4,
        3,
        4
      ],
      "state": 2
    },
    {
      "pos": [
        4,
        3,
        5
      ],
      "state": 2
    },
    {
      "pos": [
        4,
        3,
        6
      ],
      "state": 2
    },
    {
      "pos": [
        4,
        3,
        7
      ],
      "state": 2
    },
    {
      "pos": [
        4,
        3,
        8
      ],
      "state": 2
    },
    {
      "pos": [
        4,
        3,
        9
      ],
      "state": 2
    },
    {
      "pos": [
        4,
        3,
        10
      ],
      "state": 2
    },
    {
      "pos": [
        4,
        3,
        11
      ],
      "state": 2
    },
    {
      "pos": [
        4,
        3,
        12
      ],
      "state": 2
    },
    {
      "pos": [
        4,
        3,
        13
      ],
      "state": 2
    },
    {
      "pos": [
        4,
        3,
        14
      ],
      "state": 2
    },
    {
      "pos": [
        4,
        3,
        15
      ],
      "state": 2
    },
    {
      "pos": [
        4,
        3,
        16
      ],
      "state": 2
    },
    {
      "pos": [
        4,
        3,
        17
      ],
      "state": 3
    },
    {
      "pos": [
        4,
        3,
        18
      ],
      "state": 2
    },
    {
      "pos": [
        4,
        3,
        19
      ],
      "state": 2
    },
    {
      "pos": [
        4,
        3,
        20
      ],
      "state": 2
    },
    {
      "pos": [
        4,
        3,
        21
      ],
      "state": 2
    },
    {
      "pos": [
        5,
        3,
        2
      ],
      "state": 3
    },
    {
      "pos": [
        5,
        3,
        3
      ],
      "state": 3
    },
    {
      "pos": [
        5,
        3,
        4
      ],
      "state": 2
    },
    {
      "pos": [
        5,
        3,
        5
      ],
      "state": 2
    },
    {
      "pos": [
        5,
        3,
        6
      ],
      "state": 2
    },
    {
      "pos": [
        5,
        3,
        7
      ],
      "state": 2
    },
    {
      "pos": [
        5,
        3,
        8
      ],
      "state": 2
    },
    {
      "pos": [
        5,
        3,
        9
      ],
      "state": 2
    },
    {
      "pos": [
        5,
        3,
        10
      ],
      "state": 2
    },
    {
      "pos": [
        5,
        3,
        11
      ],
      "state": 3
    },
    {
      "pos": [
        5,
        3,
        12
      ],
      "state": 2
    },
    {
      "pos": [
        5,
        3,
        13
      ],
      "state": 2
    },
    {
      "pos": [
        5,
        3,
        14
      ],
      "state": 3
    },
    {
      "pos": [
        5,
        3,
        15
      ],
      "state": 2
    },
    {
      "pos": [
        5,
        3,
        16
      ],
      "state": 1
    },
    {
      "pos": [
        5,
        3,
        17
      ],
      "state": 2
    },
    {
      "pos": [
        5,
        3,
        18
      ],
      "state": 2
    },
    {
      "pos": [
        5,
        3,
        19
      ],
      "state": 2
    },
    {
      "pos": [
        5,
        3,
        20
      ],
      "state": 2
    },
    {
      "pos": [
        5,
        3,
        21
      ],
      "state": 2
    },
    {
      "pos": [
        5,
        3,
        22
      ],
      "state": 2
    },
    {
      "pos": [
        6,
        3,
        2
      ],
      "state": 2
    },
    {
      "pos": [
        6,
        3,
        3
      ],
      "state": 2
    },
    {
      "pos": [
        6,
        3,
        4
      ],
      "state": 2
    },
    {
      "pos": [
        6,
        3,
        5
      ],
      "state": 2
    },
    {
      "pos": [
        6,
        3,
        6
      ],
      "state": 1
    },
    {
      "pos": [
        6,
        3,
        7
      ],
      "state": 4
    },
    {
      "pos": [
        6,
        3,
        8
      ],
      "state": 5
    },
    {
      "pos": [
        6,
        3,
        9
      ],
      "state": 4
    },
    {
      "pos": [
        6,
        3,
        10
      ],
      "state": 5
    },
    {
      "pos": [
        6,
        3,
        11
      ],
      "state": 4
    },
    {
      "pos": [
        6,
        3,
        12
      ],
      "state": 5
    },
    {
      "pos": [
        6,
        3,
        13
      ],
      "state": 1
    },
    {
      "pos": [
        6,
        3,
        14
      ],
      "state": 1
    },
    {
      "pos": [
        6,
        3,
        15
      ],
      "state": 5
    },
    {
      "pos": [
        6,
        3,
        16
      ],
      "state": 5
    },
    {
      "pos": [
        6,
        3,
        17
      ],
      "state": 4
    },
    {
      "pos": [
        6,
        3,
        18
      ],
      "state": 1
    },
    {
      "pos": [
        6,
        3,
        19
      ],
      "state": 2
    },
    {
      "pos": [
        6,
        3,
        20
      ],
      "state": 2
    },
    {
      "pos": [
        6,
        3,
        21
      ],
      "state": 2
    },
    {
      "pos": [
        6,
        3,
        22
      ],
      "state": 2
    },
    {
      "pos": [
        7,
        3,
        1
      ],
      "state": 2
    },
    {
      "pos": [
        7,
        3,
        2
      ],
      "state": 2
    },
    {
      "pos": [
        7,
        3,
        3
      ],
      "state": 2
    },
    {
      "pos": [
        7,
        3,
        4
      ],
      "state": 2
    },
    {
      "pos": [
        7,
        3,
        5
      ],
      "state": 2
    },
    {
      "pos": [
        7,
        3,
        6
      ],
      "state": 1
    },
    {
      "pos": [
        7,
        3,
        7
      ],
      "state": 1
    },
    {
      "pos": [
        7,
        3,
        8
      ],
      "state": 4
    },
    {
      "pos": [
        7,
        3,
        9
      ],
      "state": 4
    },
    {
      "pos": [
        7,
        3,
        10
      ],
      "state": 1
    },
    {
      "pos": [
        7,
        3,
        11
      ],
      "state": 5
    },
    {
      "pos": [
        7,
        3,
        12
      ],
      "state": 1
    },
    {
      "pos": [
        7,
        3,
        13
      ],
      "state": 5
    },
    {
      "pos": [
        7,
        3,
        14
      ],
      "state": 4
    },
    {
      "pos": [
        7,
        3,
        15
      ],
      "state": 1
    },
    {
      "pos": [
        7,
        3,
        16
      ],
      "state": 4
    },
    {
      "pos": [
        7,
        3,
        17
      ],
      "state": 4
    },
    {
      "pos": [
        7,
        3,
        18
      ],
      "state": 5
    },
    {
      "pos": [
        7,
        3,
        19
      ],
      "state": 2
    },
    {
      "pos": [
        7,
        3,
        20
      ],
      "state": 2
    },
    {
      "pos": [
        7,
        3,
        21
      ],
      "state": 2
    },
    {
      "pos": [
        7,
        3,
        22
      ],
      "state": 2
    },
    {
      "pos": [
        7,
        3,
        23
      ],
      "state": 2
    },
    {
      "pos": [
        8,
        3,
        1
      ],
      "state": 2
    },
    {
      "pos": [
        8,
        3,
        2
      ],
      "state": 2
    },
    {
      "pos": [
        8,
        3,
        3
      ],
      "state": 2
    },
    {
      "pos": [
        8,
        3,
        4
      ],
      "state": 2
    },
    {
      "pos": [
        8,
        3,
        5
      ],
      "state": 2
    },
    {
      "pos": [
        8,
        3,
        6
      ],
      "state": 4
    },
    {
      "pos": [
        8,
        3,
        7
      ],
      "state": 4
    },
    {
      "pos": [
        8,
        3,
        8
      ],
      "state": 4
    },
    {
      "pos": [
        8,
        3,
        9
      ],
      "state": 1
    },
    {
      "pos": [
        8,
        3,
        10
      ],
      "state": 1
    },
    {
      "pos": [
        8,
        3,
        11
      ],
      "state": 1
    },
    {
      "pos": [
        8,
        3,
        12
      ],
      "state": 1
    },
    {
      "pos": [
        8,
        3,
        13
      ],
      "state": 1
    },
    {
      "pos": [
        8,
        3,
        14
      ],
      "state": 4
    },
    {
      "pos": [
        8,
        3,
        15
      ],
      "state": 1
    },
    {
      "pos": [
        8,
        3,
        16
      ],
      "state": 5
    },
    {
      "pos": [
        8,
        3,
        17
      ],
      "state": 1
    },
    {
      "pos": [
        8,
        3,
        18
      ],
      "state": 5
    },
    {
      "pos": [
        8,
        3,
        19
      ],
      "state": 2
    },
    {
      "pos": [
        8,
        3,
        20
      ],
      "state": 2
    },
    {
      "pos": [
        8,
        3,
        21
      ],
      "state": 2
    },
    {
      "pos": [
        8,
        3,
        22
      ],
      "state": 2
    },
    {
      "pos": [
        8,
        3,
        23
      ],
      "state": 2
    },
    {
      "pos": [
        9,
        3,
        1
      ],
      "state": 2
    },
    {
      "pos": [
        9,
        3,
        2
      ],
      "state": 1
    },
    {
      "pos": [
        9,
        3,
        3
      ],
      "state": 3
    },
    {
      "pos": [
        9,
        3,
        4
      ],
      "state": 2
    },
    {
      "pos": [
        9,
        3,
        5
      ],
      "state": 2
    },
    {
      "pos": [
        9,
        3,
        6
      ],
      "state": 5
    },
    {
      "pos": [
        9,
        3,
        7
      ],
      "state": 4
    },
    {
      "pos": [
        9,
        3,
        8
      ],
      "state": 5
    },
    {
      "pos": [
        9,
        3,
        9
      ],
      "state": 4
    },
    {
      "pos": [
        9,
        3,
        10
      ],
      "state": 1
    },
    {
      "pos": [
        9,
        3,
        11
      ],
      "state": 5
    },
    {
      "pos": [
        9,
        3,
        12
      ],
      "state": 4
    },
    {
      "pos": [
        9,
        3,
        13
      ],
      "state": 5
    },
    {
      "pos": [
        9,
        3,
        14
      ],
      "state": 5
    },
    {
      "pos": [
        9,
        3,
        15
      ],
      "state": 4
    },
    {
      "pos": [
        9,
        3,
        16
      ],
      "state": 1
    },
    {
      "pos": [
        9,
        3,
        17
      ],
      "state": 1
    },
    {
      "pos": [
        9,
        3,
        18
      ],
      "state": 4
    },
    {
      "pos": [
        9,
        3,
        19
      ],
      "state": 2
    },
    {
      "pos": [
        9,
        3,
        20
      ],
      "state": 2
    },
    {
      "pos": [
        9,
        3,
        21
      ],
      "state": 2
    },
    {
      "pos": [
        9,
        3,
        22
      ],
      "state": 1
    },
    {
      "pos": [
        9,
        3,
        23
      ],
      "state": 2
    },
    {
      "pos": [
        10,
        3,
        0
      ],
      "state": 2
    },
    {
      "pos": [
        10,
        3,
        1
      ],
      "state": 2
    },
    {
      "pos": [
        10,
        3,
        2
      ],
      "state": 2
    },
    {
      "pos": [
        10,
        3,
        3
      ],
      "state": 2
    },
    {
      "pos": [
        10,
        3,
        4
      ],
      "state": 2
    },
    {
      "pos": [
        10,
        3,
        5
      ],
      "state": 2
    },
    {
      "pos": [
        10,
        3,
        6
      ],
      "state": 1
    },
    {
      "pos": [
        10,
        3,
        7
      ],
      "state": 4
    },
    {
      "pos": [
        10,
        3,
        8
      ],
      "state": 5
    },
    {
      "pos": [
        10,
        3,
        9
      ],
      "state": 4
    },
    {
      "pos": [
        10,
        3,
        10
      ],
      "state": 1
    },
    {
      "pos": [
        10,
        3,
        11
      ],
      "state": 5
    },
    {
      "pos": [
        10,
        3,
        12
      ],
      "state": 4
    },
    {
      "pos": [
        10,
        3,
        13
      ],
      "state": 4
    },
    {
      "pos": [
        10,
        3,
        14
      ],
      "state": 5
    },
    {
      "pos": [
        10,
        3,
        15
      ],
      "state": 4
    },
    {
      "pos": [
        10,
        3,
        16
      ],
      "state": 1
    },
    {
      "pos": [
        10,
        3,
        17
      ],
      "state": 5
    },
    {
      "pos": [
        10,
        3,
        18
      ],
      "state": 5
    },
    {
      "pos": [
        10,
        3,
        19
      ],
      "state": 2
    },
    {
      "pos": [
        10,
        3,
        20
      ],
      "state": 2
    },
    {
      "pos": [
        10,
        3,
        21
      ],
      "state": 2
    },
    {
      "pos": [
        10,
        3,
        22
      ],
      "state": 2
    },
    {
      "pos": [
        10,
        3,
        23
      ],
      "state": 2
    },
    {
      "pos": [
        10,
        3,
        24
      ],
      "state": 2
    },
    {
      "pos": [
        11,
        3,
        0
      ],
      "state": 2
    },
    {
      "pos": [
        11,
        3,
        1
      ],
      "state": 3
    },
    {
      "pos": [
        11,
        3,
        2
      ],
      "state": 2
    },
    {
      "pos": [
        11,
        3,
        3
      ],
      "state": 2
    },
    {
      "pos": [
        11,
        3,
        4
      ],
      "state": 1
    },
    {
      "pos": [
        11,
        3,
        5
      ],
      "state": 3
    },
    {
      "pos": [
        11,
        3,
        6
      ],
      "state": 5
    },
    {
      "pos": [
        11,
        3,
        7
      ],
      "state": 4
    },
    {
      "pos": [
        11,
        3,
        8
      ],
      "state": 5
    },
    {
      "pos": [
        11,
        3,
        9
      ],
      "state": 1
    },
    {
      "pos": [
        11,
        3,
        10
      ],
      "state": 5
    },
    {
      "pos": [
        11,
        3,
        11
      ],
      "state": 4
    },
    {
      "pos": [
        11,
        3,
        12
      ],
      "state": 5
    },
    {
      "pos": [
        11,
        3,
        13
      ],
      "state": 5
    },
    {
      "pos": [
        11,
        3,
        14
      ],
      "state": 5
    },
    {
      "pos": [
        11,
        3,
        15
      ],
      "state": 5
    },
    {
      "pos": [
        11,
        3,
        16
      ],
      "state": 5
    },
    {
      "pos": [
        11,
        3,
        17
      ],
      "state": 5
    },
    {
      "pos": [
        11,
        3,
        18
      ],
      "state": 5
    },
    {
      "pos": [
        11,
        3,
        19
      ],
      "state": 5
    },
    {
      "pos": [
        11,
        3,
        20
      ],
      "state": 5
    },
    {
      "pos": [
        11,
        3,
        21
      ],
      "state": 5
    },
    {
      "pos": [
        11,
        3,
        22
      ],
      "state": 5
    },
    {
      "pos": [
        11,
        3,
        23
      ],
      "state": 5
    },
    {
      "pos": [
        11,
        3,
        24
      ],
      "state": 5
    },
    {
      "pos": [
        12,
        3,
        0
      ],
      "state": 2
    },
    {
      "pos": [
        12,
        3,
        1
      ],
      "state": 2
    },
    {
      "pos": [
        12,
        3,
        2
      ],
      "state": 2
    },
    {
      "pos": [
        12,
        3,
        3
      ],
      "state": 2
    },
    {
      "pos": [
        12,
        3,
        4
      ],
      "state": 2
    },
    {
      "pos": [
        12,
        3,
        5
      ],
      "state": 2
    },
    {
      "pos": [
        12,
        3,
        6
      ],
      "state": 4
    },
    {
      "pos": [
        12,
        3,
        7
      ],
      "state": 1
    },
    {
      "pos": [
        12,
        3,
        8
      ],
      "state": 1
    },
    {
      "pos": [
        12,
        3,
        9
      ],
      "state": 4
    },
    {
      "pos": [
        12,
        3,
        10
      ],
      "state": 1
    },
    {
      "pos": [
        12,
        3,
        11
      ],
      "state": 4
    },
    {
      "pos": [
        12,
        3,
        12
      ],
      "state": 6
    },
    {
      "pos": [
        12,
        3,
        13
      ],
      "state": 5
    },
    {
      "pos": [
        12,
        3,
        14
      ],
      "state": 5
    },
    {
      "pos": [
        12,
        3,
        15
      ],
      "state": 5
    },
    {
      "pos": [
        12,
        3,
        16
      ],
      "state": 5
    },
    {
      "pos": [
        12,
        3,
        17
      ],
      "state": 5
    },
    {
      "pos": [
        12,
        3,
        18
      ],
      "state": 5
    },
    {
      "pos": [
        12,
        3,
        19
      ],
      "state": 5
    },
    {
      "pos": [
        12,
        3,
        20
      ],
      "state": 5
    },
    {
      "pos": [
        12,
        3,
        21
      ],
      "state": 5
    },
    {
      "pos": [
        12,
        3,
        22
      ],
      "state": 5
    },
    {
      "pos": [
        12,
        3,
        23
      ],
      "state": 5
    },
    {
      "pos": [
        12,
        3,
        24
      ],
      "state": 5
    },
    {
      "pos": [
        13,
        3,
        0
      ],
      "state": 2
    },
    {
      "pos": [
        13,
        3,
        1
      ],
      "state": 2
    },
    {
      "pos": [
        13,
        3,
        2
      ],
      "state": 2
    },
    {
      "pos": [
        13,
        3,
        3
      ],
      "state": 2
    },
    {
      "pos": [
        13,
        3,
        4
      ],
      "state": 2
    },
    {
      "pos": [
        13,
        3,
        5
      ],
      "state": 2
    },
    {
      "pos": [
        13,
        3,
        6
      ],
      "state": 1
    },
    {
      "pos": [
        13,
        3,
        7
      ],
      "state": 4
    },
    {
      "pos": [
        13,
        3,
        8
      ],
      "state": 1
    },
    {
      "pos": [
        13,
        3,
        9
      ],
      "state": 5
    },
    {
      "pos": [
        13,
        3,
        10
      ],
      "state": 4
    },
    {
      "pos": [
        13,
        3,
        11
      ],
      "state": 4
    },
    {
      "pos": [
        13,
        3,
        12
      ],
      "state": 5
    },
    {
      "pos": [
        13,
        3,
        13
      ],
      "state": 5
    },
    {
      "pos": [
        13,
        3,
        14
      ],
      "state": 5
    },
    {
      "pos": [
        13,
        3,
        15
      ],
      "state": 5
    },
    {
      "pos": [
        13,
        3,
        16
      ],
      "state": 5
    },
    {
      "pos": [
        13,
        3,
        17
      ],
      "state": 5
    },
    {
      "pos": [
        13,
        3,
        18
      ],
      "state": 5
    },
    {
      "pos": [
        13,
        3,
        19
      ],
      "state": 5
    },
    {
      "pos": [
        13,
        3,
        20
      ],
      "state": 5
    },
    {
      "pos": [
        13,
        3,
        21
      ],
      "state": 5
    },
    {
      "pos": [
        13,
        3,
        22
      ],
      "state": 5
    },
    {
      "pos": [
        13,
        3,
        23
      ],
      "state": 5
    },
    {
      "pos": [
        13,
        3,
        24
      ],
      "state": 5
    },
    {
      "pos": [
        14,
        3,
        0
      ],
      "state": 2
    },
    {
      "pos": [
        14,
        3,
        1
      ],
      "state": 2
    },
    {
      "pos": [
        14,
        3,
        2
      ],
      "state": 2
    },
    {
      "pos": [
        14,
        3,
        3
      ],
      "state": 2
    },
    {
      "pos": [
        14,
        3,
        4
      ],
      "state": 2
    },
    {
      "pos": [
        14,
        3,
        5
      ],
      "state": 2
    },
    {
      "pos": [
        14,
        3,
        6
      ],
      "state": 1
    },
    {
      "pos": [
        14,
        3,
        7
      ],
      "state": 4
    },
    {
      "pos": [
        14,
        3,
        8
      ],
      "state": 1
    },
    {
      "pos": [
        14,
        3,
        9
      ],
      "state": 1
    },
    {
      "pos": [
        14,
        3,
        10
      ],
      "state": 1
    },
    {
      "pos": [
        14,
        3,
        11
      ],
      "state": 5
    },
    {
      "pos": [
        14,
        3,
        12
      ],
      "state": 5
    },
    {
      "pos": [
        14,
        3,
        13
      ],
      "state": 4
    },
    {
      "pos": [
        14,
        3,
        14
      ],
      "state": 5
    },
    {
      "pos": [
        14,
        3,
        15
      ],
      "state": 4
    },
    {
      "pos": [
        14,
        3,
        16
      ],
      "state": 4
    },
    {
      "pos": [
        14,
        3,
        17
      ],
      "state": 4
    },
    {
      "pos": [
        14,
        3,
        18
      ],
      "state": 5
    },
    {
      "pos": [
        14,
        3,
        19
      ],
      "state": 2
    },
    {
      "pos": [
        14,
        3,
        20
      ],
      "state": 2
    },
    {
      "pos": [
        14,
        3,
        21
      ],
      "state": 2
    },
    {
      "pos": [
        14,
        3,
        22
      ],
      "state": 1
    },
    {
      "pos": [
        14,
        3,
        23
      ],
      "state": 2
    },
    {
      "pos": [
        14,
        3,
        24
      ],
      "state": 2
    },
    {
      "pos": [
        15,
        3,
        1
      ],
      "state": 3
    },
    {
      "pos": [
        15,
        3,
        2
      ],
      "state": 2
    },
    {
      "pos": [
        15,
        3,
        3
      ],
      "state": 2
    },
    {
      "pos": [
        15,
        3,
        4
      ],
      "state": 2
    },
    {
      "pos": [
        15,
        3,
        5
      ],
      "state": 2
    },
    {
      "pos": [
        15,
        3,
        6
      ],
      "state": 1
    },
    {
      "pos": [
        15,
        3,
        7
      ],
      "state": 5
    },
    {
      "pos": [
        15,
        3,
        8
      ],
      "state": 1
    },
    {
      "pos": [
        15,
        3,
        9
      ],
      "state": 5
    },
    {
      "pos": [
        15,
        3,
        10
      ],
      "state": 1
    },
    {
      "pos": [
        15,
        3,
        11
      ],
      "state": 5
    },
    {
      "pos": [
        15,
        3,
        12
      ],
      "state": 1
    },
    {
      "pos": [
        15,
        3,
        13
      ],
      "state": 5
    },
    {
      "pos": [
        15,
        3,
        14
      ],
      "state": 4
    },
    {
      "pos": [
        15,
        3,
        15
      ],
      "state": 5
    },
    {
      "pos": [
        15,
        3,
        16
      ],
      "state": 1
    },
    {
      "pos": [
        15,
        3,
        17
      ],
      "state": 4
    },
    {
      "pos": [
        15,
        3,
        18
      ],
      "state": 1
    },
    {
      "pos": [
        15,
        3,
        19
      ],
      "state": 1
    },
    {
      "pos": [
        15,
        3,
        20
      ],
      "state": 1
    },
    {
      "pos": [
        15,
        3,
        21
      ],
      "state": 2
    },
    {
      "pos": [
        15,
        3,
        22
      ],
      "state": 3
    },
    {
      "pos": [
        15,
        3,
        23
      ],
      "state": 2
    },
    {
      "pos": [
        16,
        3,
        1
      ],
      "state": 2
    },
    {
      "pos": [
        16,
        3,
        2
      ],
      "state": 2
    },
    {
      "pos": [
        16,
        3,
        3
      ],
      "state": 3
    },
    {
      "pos": [
        16,
        3,
        4
      ],
      "state": 2
    },
    {
      "pos": [
        16,
        3,
        5
      ],
      "state": 2
    },
    {
      "pos": [
        16,
        3,
        6
      ],
      "state": 5
    },
    {
      "pos": [
        16,
        3,
        7
      ],
      "state": 5
    },
    {
      "pos": [
        16,
        3,
        8
      ],
      "state": 1
    },
    {
      "pos": [
        16,
        3,
        9
      ],
      "state": 4
    },
    {
      "pos": [
        16,
        3,
        10
      ],
      "state": 1
    },
    {
      "pos": [
        16,
        3,
        11
      ],
      "state": 4
    },
    {
      "pos": [
        16,
        3,
        12
      ],
      "state": 5
    },
    {
      "pos": [
        16,
        3,
        13
      ],
      "state": 5
    },
    {
      "pos": [
        16,
        3,
        14
      ],
      "state": 1
    },
    {
      "pos": [
        16,
        3,
        15
      ],
      "state": 5
    },
    {
      "pos": [
        16,
        3,
        16
      ],
      "state": 4
    },
    {
      "pos": [
        16,
        3,
        17
      ],
      "state": 4
    },
    {
      "pos": [
        16,
        3,
        18
      ],
      "state": 4
    },
    {
      "pos": [
        16,
        3,
        19
      ],
      "state": 2
    },
    {
      "pos": [
        16,
        3,
        20
      ],
      "state": 2
    },
    {
      "pos": [
        16,
        3,
        21
      ],
      "state": 1
    },
    {
      "pos": [
        16,
        3,
        22
      ],
      "state": 2
    },
    {
      "pos": [
        16,
        3,
        23
      ],
      "state": 2
    },
    {
      "pos": [
        17,
        3,
        1
      ],
      "state": 2
    },
    {
      "pos": [
        17,
        3,
        2
      ],
      "state": 1
    },
    {
      "pos": [
        17,
        3,
        3
      ],
      "state": 2
    },
    {
      "pos": [
        17,
        3,
        4
      ],
      "state": 1
    },
    {
      "pos": [
        17,
        3,
        5
      ],
      "state": 1
    },
    {
      "pos": [
        17,
        3,
        6
      ],
      "state": 1
    },
    {
      "pos": [
        17,
        3,
        7
      ],
      "state": 1
    },
    {
      "pos": [
        17,
        3,
        8
      ],
      "state": 4
    },
    {
      "pos": [
        17,
        3,
        9
      ],
      "state": 4
    },
    {
      "pos": [
        17,
        3,
        10
      ],
      "state": 4
    },
    {
      "pos": [
        17,
        3,
        11
      ],
      "state": 5
    },
    {
      "pos": [
        17,
        3,
        12
      ],
      "state": 1
    },
    {
      "pos": [
        17,
        3,
        13
      ],
      "state": 5
    },
    {
      "pos": [
        17,
        3,
        14
      ],
      "state": 5
    },
    {
      "pos": [
        17,
        3,
        15
      ],
      "state": 1
    },
    {
      "pos": [
        17,
        3,
        16
      ],
      "state": 5
    },
    {
      "pos": [
        17,
        3,
        17
      ],
      "state": 5
    },
    {
      "pos": [
        17,
        3,
        18
      ],
      "state": 5
    },
    {
      "pos": [
        17,
        3,
        19
      ],
      "state": 2
    },
    {
      "pos": [
        17,
        3,
        20
      ],
      "state": 2
    },
    {
      "pos": [
        17,
        3,
        21
      ],
      "state": 2
    },
    {
      "pos": [
        17,
        3,
        22
      ],
      "state": 3
    },
    {
      "pos": [
        17,
        3,
        23
      ],
      "state": 2
    },
    {
      "pos": [
        18,
        3,
        2
      ],
      "state": 3
    },
    {
      "pos": [
        18,
        3,
        3
      ],
      "state": 2
    },
    {
      "pos": [
        18,
        3,
        4
      ],
      "state": 2
    },
    {
      "pos": [
        18,
        3,
        5
      ],
      "state": 2
    },
    {
      "pos": [
        18,
        3,
        6
      ],
      "state": 5
    },
    {
      "pos": [
        18,
        3,
        7
      ],
      "state": 5
    },
    {
      "pos": [
        18,
        3,
        8
      ],
      "state": 5
    },
    {
      "pos": [
        18,
        3,
        9
      ],
      "state": 4
    },
    {
      "pos": [
        18,
        3,
        10
      ],
      "state": 4
    },
    {
      "pos": [
        18,
        3,
        11
      ],
      "state": 1
    },
    {
      "pos": [
        18,
        3,
        12
      ],
      "state": 5
    },
    {
      "pos": [
        18,
        3,
        13
      ],
      "state": 4
    },
    {
      "pos": [
        18,
        3,
        14
      ],
      "state": 1
    },
    {
      "pos": [
        18,
        3,
        15
      ],
      "state": 5
    },
    {
      "pos": [
        18,
        3,
        16
      ],
      "state": 1
    },
    {
      "pos": [
        18,
        3,
        17
      ],
      "state": 5
    },
    {
      "pos": [
        18,
        3,
        18
      ],
      "state": 1
    },
    {
      "pos": [
        18,
        3,
        19
      ],
      "state": 2
    },
    {
      "pos": [
        18,
        3,
        20
      ],
      "state": 2
    },
    {
      "pos": [
        18,
        3,
        21
      ],
      "state": 2
    },
    {
      "pos": [
        18,
        3,
        22
      ],
      "state": 2
    },
    {
      "pos": [
        19,
        3,
        2
      ],
      "state": 1
    },
    {
      "pos": [
        19,
        3,
        3
      ],
      "state": 2
    },
    {
      "pos": [
        19,
        3,
        4
      ],
      "state": 2
    },
    {
      "pos": [
        19,
        3,
        5
      ],
      "state": 2
    },
    {
      "pos": [
        19,
        3,
        6
      ],
      "state": 2
    },
    {
      "pos": [
        19,
        3,
        7
      ],
      "state": 2
    },
    {
      "pos": [
        19,
        3,
        8
      ],
      "state": 2
    },
    {
      "pos": [
        19,
        3,
        9
      ],
      "state": 2
    },
    {
      "pos": [
        19,
        3,
        10
      ],
      "state": 2
    },
    {
      "pos": [
        19,
        3,
        11
      ],
      "state": 2
    },
    {
      "pos": [
        19,
        3,
        12
      ],
      "state": 7
    },
    {
      "pos": [
        19,
        3,
        13
      ],
      "state": 2
    },
    {
      "pos": [
        19,
        3,
        14
      ],
      "state": 2
    },
    {
      "pos": [
        19,
        3,
        15
      ],
      "state": 2
    },
    {
      "pos": [
        19,
        3,
        16
      ],
      "state": 2
    },
    {
      "pos": [
        19,
        3,
        17
      ],
      "state": 2
    },
    {
      "pos": [
        19,
        3,
        18
      ],
      "state": 2
    },
    {
      "pos": [
        19,
        3,
        19
      ],
      "state": 2
    },
    {
      "pos": [
        19,
        3,
        20
      ],
      "state": 1
    },
    {
      "pos": [
        19,
        3,
        21
      ],
      "state": 2
    },
    {
      "pos": [
        19,
        3,
        22
      ],
      "state": 2
    },
    {
      "pos": [
        20,
        3,
        3
      ],
      "state": 2
    },
    {
      "pos": [
        20,
        3,
        4
      ],
      "state": 2
    },
    {
      "pos": [
        20,
        3,
        5
      ],
      "state": 2
    },
    {
      "pos": [
        20,
        3,
        6
      ],
      "state": 2
    },
    {
      "pos": [
        20,
        3,
        7
      ],
      "state": 2
    },
    {
      "pos": [
        20,
        3,
        8
      ],
      "state": 3
    },
    {
      "pos": [
        20,
        3,
        9
      ],
      "state": 3
    },
    {
      "pos": [
        20,
        3,
        10
      ],
      "state": 3
    },
    {
      "pos": [
        20,
        3,
        11
      ],
      "state": 7
    },
    {
      "pos": [
        20,
        3,
        12
      ],
      "state": 7
    },
    {
      "pos": [
        20,
        3,
        13
      ],
      "state": 7
    },
    {
      "pos": [
        20,
        3,
        14
      ],
      "state": 1
    },
    {
      "pos": [
        20,
        3,
        15
      ],
      "state": 2
    },
    {
      "pos": [
        20,
        3,
        16
      ],
      "state": 1
    },
    {
      "pos": [
        20,
        3,
        17
      ],
      "state": 2
    },
    {
      "pos": [
        20,
        3,
        18
      ],
      "state": 2
    },
    {
      "pos": [
        20,
        3,
        19
      ],
      "state": 2
    },
    {
      "pos": [
        20,
        3,
        20
      ],
      "state": 2
    },
    {
      "pos": [
        20,
        3,
        21
      ],
      "state": 3
    },
    {
      "pos": [
        21,
        3,
        4
      ],
      "state": 3
    },
    {
      "pos": [
        21,
        3,
        5
      ],
      "state": 2
    },
    {
      "pos": [
        21,
        3,
        6
      ],
      "state": 2
    },
    {
      "pos": [
        21,
        3,
        7
      ],
      "state": 2
    },
    {
      "pos": [
        21,
        3,
        8
      ],
      "state": 2
    },
    {
      "pos": [
        21,
        3,
        9
      ],
      "state": 3
    },
    {
      "pos": [
        21,
        3,
        10
      ],
      "state": 2
    },
    {
      "pos": [
        21,
        3,
        11
      ],
      "state": 3
    },
    {
      "pos": [
        21,
        3,
        12
      ],
      "state": 7
    },
    {
      "pos": [
        21,
        3,
        13
      ],
      "state": 2
    },
    {
      "pos": [
        21,
        3,
        14
      ],
      "state": 2
    },
    {
      "pos": [
        21,
        3,
        15
      ],
      "state": 2
    },
    {
      "pos": [
        21,
        3,
        16
      ],
      "state": 2
    },
    {
      "pos": [
        21,
        3,
        17
      ],
      "state": 1
    },
    {
      "pos": [
        21,
        3,
        18
      ],
      "state": 2
    },
    {
      "pos": [
        21,
        3,
        19
      ],
      "state": 2
    },
    {
      "pos": [
        21,
        3,
        20
      ],
      "state": 2
    },
    {
      "pos": [
        22,
        3,
        5
      ],
      "state": 2
    },
    {
      "pos": [
        22,
        3,
        6
      ],
      "state": 1
    },
    {
      "pos": [
        22,
        3,
        7
      ],
      "state": 2
    },
    {
      "pos": [
        22,
        3,
        8
      ],
      "state": 2
    },
    {
      "pos": [
        22,
        3,
        9
      ],
      "state": 1
    },
    {
      "pos": [
        22,
        3,
        10
      ],
      "state": 2
    },
    {
      "pos": [
        22,
        3,
        11
      ],
      "state": 2
    },
    {
      "pos": [
        22,
        3,
        12
      ],
      "state": 2
    },
    {
      "pos": [
        22,
        3,
        13
      ],
      "state": 1
    },
    {
      "pos": [
        22,
        3,
        14
      ],
      "state": 2
    },
    {
      "pos": [
        22,
        3,
        15
      ],
      "state": 2
    },
    {
      "pos": [
        22,
        3,
        16
      ],
      "state": 1
    },
    {
      "pos": [
        22,
        3,
        17
      ],
      "state": 2
    },
    {
      "pos": [
        22,
        3,
        18
      ],
      "state": 2
    },
    {
      "pos": [
        22,
        3,
        19
      ],
      "state": 2
    },
    {
      "pos": [
        23,
        3,
        7
      ],
      "state": 2
    },
    {
      "pos": [
        23,
        3,
        8
      ],
      "state": 1
    },
    {
      "pos": [
        23,
        3,
        9
      ],
      "state": 2
    },
    {
      "pos": [
        23,
        3,
        10
      ],
      "state": 2
    },
    {
      "pos": [
        23,
        3,
        11
      ],
      "state": 1
    },
    {
      "pos": [
        23,
        3,
        12
      ],
      "state": 2
    },
    {
      "pos": [
        23,
        3,
        13
      ],
      "state": 2
    },
    {
      "pos": [
        23,
        3,
        14
      ],
      "state": 2
    },
    {
      "pos": [
        23,
        3,
        15
      ],
      "state": 2
    },
    {
      "pos": [
        23,
        3,
        16
      ],
      "state": 2
    },
    {
      "pos": [
        23,
        3,
        17
      ],
      "state": 2
    },
    {
      "pos": [
        24,
        3,
        10
      ],
      "state": 2
    },
    {
      "pos": [
        24,
        3,
        11
      ],
      "state": 2
    },
    {
      "pos": [
        24,
        3,
        12
      ],
      "state": 2
    },
    {
      "pos": [
        24,
        3,
        13
      ],
      "state": 2
    },
    {
      "pos": [
        24,
        3,
        14
      ],
      "state": 2
    },
    {
      "pos": [
        1,
        4,
        20
      ],
      "state": 9
    },
    {
      "pos": [
        1,
        4,
        21
      ],
      "state": 9
    },
    {
      "pos": [
        2,
        4,
        8
      ],
      "state": 10
    },
    {
      "pos": [
        2,
        4,
        16
      ],
      "state": 10
    },
    {
      "pos": [
        2,
        4,
        20
      ],
      "state": 9
    },
    {
      "pos": [
        2,
        4,
        21
      ],
      "state": 9
    },
    {
      "pos": [
        3,
        4,
        20
      ],
      "state": 9
    },
    {
      "pos": [
        3,
        4,
        21
      ],
      "state": 9
    },
    {
      "pos": [
        4,
        4,
        20
      ],
      "state": 9
    },
    {
      "pos": [
        4,
        4,
        21
      ],
      "state": 9
    },
    {
      "pos": [
        7,
        4,
        1
      ],
      "state": 11
    },
    {
      "pos": [
        7,
        4,
        5
      ],
      "state": 12
    },
    {
      "pos": [
        8,
        4,
        1
      ],
      "state": 11
    },
    {
      "pos": [
        8,
        4,
        2
      ],
      "state": 13
    },
    {
      "pos": [
        8,
        4,
        3
      ],
      "state": 13
    },
    {
      "pos": [
        9,
        4,
        1
      ],
      "state": 11
    },
    {
      "pos": [
        9,
        4,
        2
      ],
      "state": 13
    },
    {
      "pos": [
        9,
        4,
        3
      ],
      "state": 13
    },
    {
      "pos": [
        10,
        4,
        1
      ],
      "state": 11
    },
    {
      "pos": [
        10,
        4,
        2
      ],
      "state": 13
    },
    {
      "pos": [
        10,
        4,
        3
      ],
      "state": 13
    },
    {
      "pos": [
        11,
        4,
        1
      ],
      "state": 11
    },
    {
      "pos": [
        12,
        4,
        1
      ],
      "state": 11
    },
    {
      "pos": [
        12,
        4,
        2
      ],
      "state": 14,
      "nbt": {
        "id": "minecraft:chest",
        "LootTable": "darkspawn:chests/hunter_camp"
      }
    },
    {
      "pos": [
        13,
        4,
        1
      ],
      "state": 11
    },
    {
      "pos": [
        14,
        4,
        1
      ],
      "state": 11
    },
    {
      "pos": [
        14,
        4,
        2
      ],
      "state": 15
    },
    {
      "pos": [
        14,
        4,
        3
      ],
      "state": 15
    },
    {
      "pos": [
        15,
        4,
        1
      ],
      "state": 11
    },
    {
      "pos": [
        15,
        4,
        2
      ],
      "state": 15
    },
    {
      "pos": [
        15,
        4,
        3
      ],
      "state": 15
    },
    {
      "pos": [
        16,
        4,
        1
      ],
      "state": 11
    },
    {
      "pos": [
        16,
        4,
        2
      ],
      "state": 15
    },
    {
      "pos": [
        16,
        4,
        3
      ],
      "state": 15
    },
    {
      "pos": [
        17,
        4,
        1
      ],
      "state": 11
    },
    {
      "pos": [
        17,
        4,
        5
      ],
      "state": 12
    },
    {
      "pos": [
        20,
        4,
        12
      ],
      "state": 16
    },
    {
      "pos": [
        22,
        4,
        8
      ],
      "state": 10
    },
    {
      "pos": [
        22,
        4,
        9
      ],
      "state": 17
    },
    {
      "pos": [
        22,
        4,
        10
      ],
      "state": 17
    },
    {
      "pos": [
        22,
        4,
        11
      ],
      "state": 17
    },
    {
      "pos": [
        22,
        4,
        12
      ],
      "state": 17
    },
    {
      "pos": [
        22,
        4,
        13
      ],
      "state": 17
    },
    {
      "pos": [
        22,
        4,
        14
      ],
      "state": 17
    },
    {
      "pos": [
        22,
        4,
        15
      ],
      "state": 17
    },
    {
      "pos": [
        22,
        4,
        16
      ],
      "state": 10
    },
    {
      "pos": [
        2,
        5,
        8
      ],
      "state": 18
    },
    {
      "pos": [
        2,
        5,
        16
      ],
      "state": 18
    },
    {
      "pos": [
        3,
        5,
        20
      ],
      "state": 19
    },
    {
      "pos": [
        7,
        5,
        1
      ],
      "state": 11
    },
    {
      "pos": [
        7,
        5,
        5
      ],
      "state": 12
    },
    {
      "pos": [
        8,
        5,
        1
      ],
      "state": 11
    },
    {
      "pos": [
        9,
        5,
        1
      ],
      "state": 11
    },
    {
      "pos": [
        10,
        5,
        1
      ],
      "state": 11
    },
    {
      "pos": [
        11,
        5,
        1
      ],
      "state": 11
    },
    {
      "pos": [
        12,
        5,
        1
      ],
      "state": 11
    },
    {
      "pos": [
        13,
        5,
        1
      ],
      "state": 11
    },
    {
      "pos": [
        14,
        5,
        1
      ],
      "state": 11
    },
    {
      "pos": [
        15,
        5,
        1
      ],
      "state": 11
    },
    {
      "pos": [
        16,
        5,
        1
      ],
      "state": 11
    },
    {
      "pos": [
        17,
        5,
        1
      ],
      "state": 11
    },
    {
      "pos": [
        17,
        5,
        5
      ],
      "state": 12
    },
    {
      "pos": [
        22,
        5,
        8
      ],
      "state": 20
    },
    {
      "pos": [
        22,
        5,
        16
      ],
      "state": 20
    },
    {
      "pos": [
        2,
        6,
        8
      ],
      "state": 10
    },
    {
      "pos": [
        2,
        6,
        16
      ],
      "state": 10
    },
    {
      "pos": [
        7,
        6,
        1
      ],
      "state": 12
    },
    {
      "pos": [
        7,
        6,
        5
      ],
      "state": 12
    },
    {
      "pos": [
        17,
        6,
        1
      ],
      "state": 12
    },
    {
      "pos": [
        17,
        6,
        5
      ],
      "state": 12
    },
    {
      "pos": [
        22,
        6,
        8
      ],
      "state": 10
    },
    {
      "pos": [
        22,
        6,
        16
      ],
      "state": 10
    },
    {
      "pos": [
        6,
        7,
        0
      ],
      "state": 21
    },
    {
      "pos": [
        6,
        7,
        1
      ],
      "state": 21
    },
    {
      "pos": [
        6,
        7,
        5
      ],
      "state": 21
    },
    {
      "pos": [
        6,
        7,
        6
      ],
      "state": 21
    },
    {
      "pos": [
        7,
        7,
        0
      ],
      "state": 21
    },
    {
      "pos": [
        7,
        7,
        1
      ],
      "state": 21
    },
    {
      "pos": [
        7,
        7,
        5
      ],
      "state": 21
    },
    {
      "pos": [
        7,
        7,
        6
      ],
      "state": 21
    },
    {
      "pos": [
        8,
        7,
        0
      ],
      "state": 21
    },
    {
      "pos": [
        8,
        7,
        1
      ],
      "state": 21
    },
    {
      "pos": [
        8,
        7,
        5
      ],
      "state": 21
    },
    {
      "pos": [
        8,
        7,
        6
      ],
      "state": 21
    },
    {
      "pos": [
        9,
        7,
        0
      ],
      "state": 21
    },
    {
      "pos": [
        9,
        7,
        1
      ],
      "state": 21
    },
    {
      "pos": [
        9,
        7,
        5
      ],
      "state": 21
    },
    {
      "pos": [
        9,
        7,
        6
      ],
      "state": 21
    },
    {
      "pos": [
        10,
        7,
        0
      ],
      "state": 21
    },
    {
      "pos": [
        10,
        7,
        1
      ],
      "state": 21
    },
    {
      "pos": [
        10,
        7,
        5
      ],
      "state": 21
    },
    {
      "pos": [
        10,
        7,
        6
      ],
      "state": 21
    },
    {
      "pos": [
        11,
        7,
        0
      ],
      "state": 21
    },
    {
      "pos": [
        11,
        7,
        1
      ],
      "state": 21
    },
    {
      "pos": [
        11,
        7,
        5
      ],
      "state": 21
    },
    {
      "pos": [
        11,
        7,
        6
      ],
      "state": 21
    },
    {
      "pos": [
        12,
        7,
        0
      ],
      "state": 21
    },
    {
      "pos": [
        12,
        7,
        1
      ],
      "state": 21
    },
    {
      "pos": [
        12,
        7,
        5
      ],
      "state": 21
    },
    {
      "pos": [
        12,
        7,
        6
      ],
      "state": 21
    },
    {
      "pos": [
        13,
        7,
        0
      ],
      "state": 21
    },
    {
      "pos": [
        13,
        7,
        1
      ],
      "state": 21
    },
    {
      "pos": [
        13,
        7,
        5
      ],
      "state": 21
    },
    {
      "pos": [
        13,
        7,
        6
      ],
      "state": 21
    },
    {
      "pos": [
        14,
        7,
        0
      ],
      "state": 21
    },
    {
      "pos": [
        14,
        7,
        1
      ],
      "state": 21
    },
    {
      "pos": [
        14,
        7,
        5
      ],
      "state": 21
    },
    {
      "pos": [
        14,
        7,
        6
      ],
      "state": 21
    },
    {
      "pos": [
        15,
        7,
        0
      ],
      "state": 21
    },
    {
      "pos": [
        15,
        7,
        1
      ],
      "state": 21
    },
    {
      "pos": [
        15,
        7,
        5
      ],
      "state": 21
    },
    {
      "pos": [
        15,
        7,
        6
      ],
      "state": 21
    },
    {
      "pos": [
        16,
        7,
        0
      ],
      "state": 21
    },
    {
      "pos": [
        16,
        7,
        1
      ],
      "state": 21
    },
    {
      "pos": [
        16,
        7,
        5
      ],
      "state": 21
    },
    {
      "pos": [
        16,
        7,
        6
      ],
      "state": 21
    },
    {
      "pos": [
        17,
        7,
        0
      ],
      "state": 21
    },
    {
      "pos": [
        17,
        7,
        1
      ],
      "state": 21
    },
    {
      "pos": [
        17,
        7,
        5
      ],
      "state": 21
    },
    {
      "pos": [
        17,
        7,
        6
      ],
      "state": 21
    },
    {
      "pos": [
        18,
        7,
        0
      ],
      "state": 21
    },
    {
      "pos": [
        18,
        7,
        1
      ],
      "state": 21
    },
    {
      "pos": [
        18,
        7,
        5
      ],
      "state": 21
    },
    {
      "pos": [
        18,
        7,
        6
      ],
      "state": 21
    },
    {
      "pos": [
        6,
        8,
        2
      ],
      "state": 21
    },
    {
      "pos": [
        6,
        8,
        3
      ],
      "state": 21
    },
    {
      "pos": [
        6,
        8,
        4
      ],
      "state": 21
    },
    {
      "pos": [
        7,
        8,
        2
      ],
      "state": 21
    },
    {
      "pos": [
        7,
        8,
        3
      ],
      "state": 21
    },
    {
      "pos": [
        7,
        8,
        4
      ],
      "state": 21
    },
    {
      "pos": [
        8,
        8,
        2
      ],
      "state": 21
    },
    {
      "pos": [
        8,
        8,
        3
      ],
      "state": 21
    },
    {
      "pos": [
        8,
        8,
        4
      ],
      "state": 21
    },
    {
      "pos": [
        9,
        8,
        2
      ],
      "state": 21
    },
    {
      "pos": [
        9,
        8,
        3
      ],
      "state": 21
    },
    {
      "pos": [
        9,
        8,
        4
      ],
      "state": 21
    },
    {
      "pos": [
        10,
        8,
        2
      ],
      "state": 21
    },
    {
      "pos": [
        10,
        8,
        3
      ],
      "state": 21
    },
    {
      "pos": [
        10,
        8,
        4
      ],
      "state": 21
    },
    {
      "pos": [
        11,
        8,
        2
      ],
      "state": 21
    },
    {
      "pos": [
        11,
        8,
        3
      ],
      "state": 21
    },
    {
      "pos": [
        11,
        8,
        4
      ],
      "state": 21
    },
    {
      "pos": [
        12,
        8,
        2
      ],
      "state": 21
    },
    {
      "pos": [
        12,
        8,
        3
      ],
      "state": 21
    },
    {
      "pos": [
        12,
        8,
        4
      ],
      "state": 21
    },
    {
      "pos": [
        13,
        8,
        2
      ],
      "state": 21
    },
    {
      "pos": [
        13,
        8,
        3
      ],
      "state": 21
    },
    {
      "pos": [
        13,
        8,
        4
      ],
      "state": 21
    },
    {
      "pos": [
        14,
        8,
        2
      ],
      "state": 21
    },
    {
      "pos": [
        14,
        8,
        3
      ],
      "state": 21
    },
    {
      "pos": [
        14,
        8,
        4
      ],
      "state": 21
    },
    {
      "pos": [
        15,
        8,
        2
      ],
      "state": 21
    },
    {
      "pos": [
        15,
        8,
        3
      ],
      "state": 21
    },
    {
      "pos": [
        15,
        8,
        4
      ],
      "state": 21
    },
    {
      "pos": [
        16,
        8,
        2
      ],
      "state": 21
    },
    {
      "pos": [
        16,
        8,
        3
      ],
      "state": 21
    },
    {
      "pos": [
        16,
        8,
        4
      ],
      "state": 21
    },
    {
      "pos": [
        17,
        8,
        2
      ],
      "state": 21
    },
    {
      "pos": [
        17,
        8,
        3
      ],
      "state": 21
    },
    {
      "pos": [
        17,
        8,
        4
      ],
      "state": 21
    },
    {
      "pos": [
        18,
        8,
        2
      ],
      "state": 21
    },
    {
      "pos": [
        18,
        8,
        3
      ],
      "state": 21
    },
    {
      "pos": [
        18,
        8,
        4
      ],
      "state": 21
    }
  ]
}
